Workbook

Sheet 00_결론요약
A1: V2 vs V3 정성 산출물 비교 — 결론
A2: 비교 대상: V2 consultant_safe_v10_1!G열 ↔ V3 Qualitative!H열 · EBX Indicator 95개 정합 · 양쪽 작성분 65개 직접 비교
A4: 한 줄 결론
A5: 두 버전은 서로 다른 실패를 합니다. V2는 "많이 쓰지만 근거보다 앞서 나가고", V3는 "근거 안에 머물지만 항목을 못 채우고 기계 티가 납니다". 보고서 초안으로 바로 쓰기에는 V2가, 사실 검증 리스크가 낮은 재료로는 V3가 낫습니다. 두 관점 모두에서 총점은 V2가 앞서지만, V3의 패인 대부분은 문장력이 아니라 제거 가능한 파이프라인 결함(출처 헤지구, 과보수적 QA 차단)입니다.
A7: V2가 우세한 항목
A8: 완전성(작성률 86.3% vs 73.7%) · 항목 적합성(0.856 vs 0.612, 43/65승) · 구체성(1천자당 숫자 23.3 vs 12.8) · 균형성(리스크 언급 59.8% vs 37.1%) · 문장 자연스러움(기계적 삽입구 0건 vs 24건).
A10: V3가 우세한 항목
A11: 근거 충실성·검증가능성(0.408 → 0.629, 59/65승 — 가장 큰 격차) · 상투어 절제(1천자당 5.79 → 3.78).
A13: 사실상 동률인 항목
A14: 어휘 다양성(MATTR 0.9386 vs 0.9380) · 명확성(평균 문장 93.0자 vs 94.1자) · 문체 리듬 다양성(길이 통제 시 CV 0.242 vs 0.249).
A16: ★ 오판하기 쉬운 지점
A17: 전체 평균만 보면 V2의 버스티니스(문장 길이 변동)가 훨씬 높아 "V2가 더 사람 같다"는 결론이 나옵니다. 하지만 이는 V3 답변이 평균 2.3문장으로 짧아서 생긴 착시입니다. 3문장 이상인 28건만 비교하면 0.242 vs 0.249로 오히려 V3가 근소 우위입니다. 어휘 다양성도 마찬가지로 길이를 맞추면 차이가 사라집니다. 즉 두 버전의 문장력 자체에는 유의미한 차이가 없고, 차이는 전부 "무엇을 얼마나 쓸 것인가"라는 정책에서 나옵니다.
... A28: 총점 (02_종합비교 시트 연동)
A29: 관점 | B29: V2 | C29: V3 | D29: 우세
A30: 가중치A — 보고서 초안 품질 | B30: ='02_종합비교'!B17 -> 80.8 | C30: ='02_종합비교'!C17 -> 70 | D30: ='02_종합비교'!D17 -> V2 우세
A31: 가중치B — 사람이 쓴 글 같은가 | B31: ='02_종합비교'!B18 -> 83.2 | C31: ='02_종합비교'!C18 -> 67 | D31: ='02_종합비교'!D18 -> V2 우세
A32: 항목 승패 (10개 항목) | B32: ='02_종합비교'!B20 -> 5 | C32: ='02_종합비교'!C20 -> 2 | D32: ='02_종합비교'!D20 -> 3건 동률

Sheet 01_평가기준
A1: 정성 산출물 V2 vs V3 비교 — 평가 기준 설계
A2: V2: [langgraph][daewoong-company]final_report(2026.08.10) — 시트 consultant_safe_v10_1 · G열 Final Answer
A3: V3: [langgraph][v3][Daewoong]report-2026.08.11_9 — 시트 Qualitative · H열 Final Answer
A4: A열 EBX Indicator 기준으로 정합 — 양쪽 모두 95개 지표, 100% 일치 (누락·초과 없음). 둘 다 작성된 65개가 직접 비교 대상.
A6: 왜 이 기준인가
A7: "사람이 쓴 것 같은가"는 단일 척도로 측정되지 않습니다. 문헌상 두 갈래가 별개로 다뤄집니다. (1) 내용 품질 — 지속가능경영보고서라는 장르 자체의 품질 기준은 GRI 1: Foundation 2021의 보고원칙(정확성·균형·명확성·비교가능성·완전성·검증가능성)이 사실상 표준입니다. (2) 문체 인간유사성 — AI 텍스트 탐지 연구는 일관되게 문장 길이 변동(버스티니스), 어휘 다양성, 상투구 반복률을 인간/기계 구분 신호로 씁니다. 여기에 NLG 인간평가에서 표준적으로 쓰이는 축(유창성·충실성·정보성)을 겹쳐 10개 항목을 구성했습니다. 각 항목은 이 두 파일에서 실제로 계산 가능한 대리지표(proxy)로만 정의했습니다 — 주관적 인상 점수는 넣지 않았습니다.
A9: 항목 | B9: 무엇을 보는가 | C9: 측정 방법(이 파일에서 실제 계산한 값) | D9: 근거 문헌 | E9: 가중치A(보고품질) | F9: 가중치B(인간유사성)
A10: C1 완전성 | B10: 요구된 95개 지표 중 실제로 글이 채워진 비율 | C10: 비어있지 않은 셀 비율 | D10: GRI 1 — Completeness | E10: 12 | F10: 5
A11: C2 항목 적합성 | B11: Field(항목명)가 요구하는 주제를 본문이 실제로 다루는가 | C11: Field 말단 키워드가 본문에 출현하는 비율 | D11: GRI 1 — Completeness / NLG Relevance | E11: 12 | F11: 8
A12: C3 근거 충실성·검증가능성 | B12: 본문이 Original Evidence에 실제로 근거하는가(=지어내지 않았는가) | C12: 본문 문자 4-gram 중 Evidence에도 존재하는 비율 | D12: GRI 1 — Accuracy, Verifiability / NLG Faithfulness | E12: 18 | F12: 10
A13: C4 균형성 | B13: 성과만 나열하지 않고 리스크·미흡·과제도 언급하는가 | C13: 부정·과제 어휘(리스크/미흡/한계/개선 필요 등) 포함 답변 비율 | D13: GRI 1 — Balance | E13: 10 | F13: 8
A14: C5 구체성 | B14: 수치·연도·고유명사 등 검증 가능한 사실이 들어있는가 | C14: 1천자당 숫자 출현 수, 연도 언급 답변 비율 | D14: GRI 1 — Accuracy / NLG Informativeness | E14: 10 | F14: 10
A15: C6 명확성 | B15: 한 문장이 지나치게 길어 독해를 방해하지 않는가 | C15: 평균 문장 길이, 120자 초과 장문 비율 | D15: GRI 1 — Clarity | E15: 10 | F15: 14
A16: C7 문장 자연스러움·문법 무결성 | B16: 사람이 쓴 문장으로 읽히는가 / 기계적 삽입구가 없는가 | C16: 출처 헤지구("~자료상") 출현 답변 비율, 문장 중간 접속 파손 건수 | D16: NLG Human Eval — Fluency | E16: 12 | F16: 22
A17: C8 문체 리듬 다양성(버스티니스) | B17: 문장 길이가 단조롭지 않고 인간처럼 들쭉날쭉한가 | C17: 문장 길이 변동계수(CV) — 3문장 이상 답변으로 길이 통제 | D17: AI 탐지 문헌 — Burstiness | E17: 5 | F17: 10
A18: C9 상투어·템플릿 회피 | B18: "지속적으로/적극적으로/체계적으로" 류 무내용 표현이 과하지 않은가 | C18: 1천자당 상투어 출현 수(낮을수록 우수) | D18: AI 탐지 문헌 — Lexical repetitiveness | E18: 6 | F18: 9
A19: C10 어휘 다양성 | B19: 같은 단어를 돌려쓰지 않는가 | C19: MATTR(이동창 40어절 Type-Token Ratio) — 길이 통제 | D19: AI 탐지 문헌 — Lexical density / TTR | E19: 5 | F19: 4
A20: 합계 | E20: =SUM(E10:E19) -> 100 | F20: =SUM(F10:F19) -> 100
A22: 가중치 두 벌을 쓰는 이유
A23: 가중치A는 "보고서 초안으로서 얼마나 쓸 만한가"를 봅니다 — 근거 충실성과 완전성에 무게를 둡니다. 가중치B는 요청하신 "사람이 쓴 것과 얼마나 비슷한가"를 봅니다 — 유창성·명확성·문체 지표에 무게를 둡니다. 두 관점에서 승자가 갈릴 수 있으므로 분리했습니다. 가중치는 조정 가능한 입력값입니다(E·F열, 노란색).
A25: 출처
A26: · GRI 1: Foundation 2021 — 보고원칙 8개(정확성·균형·명확성·비교가능성·완전성·지속가능성 맥락·적시성·검증가능성). globalreporting.org
A27: · Howcroft et al. (2020), "Twenty Years of Confusion in Human Evaluation", INLG — NLG 인간평가 표준 축(유창성/충실성/정보성). aclanthology.org/2020.inlg-1.23
A28: · AI 생성문 탐지 문헌 — AI 텍스트는 인간 대비 문장 길이가 균일(낮은 버스티니스)하고 어휘 반복률이 높다는 것이 공통 관찰. 단, 버스티니스·퍼플렉시티는 단독 지표로는 오판율이 높다는 반론(Pangram)도 함께 반영해 보조 지표로만 사용.
A29: · 주의: 적시성·비교가능성·지속가능성 맥락은 단일 문단 단위로는 판정할 수 없어 평가에서 제외했습니다.

Sheet 02_종합비교
A1: 종합 비교 스코어카드 — V2 vs V3
A2: 점수 5점 척도. 점수는 04_항목별비교의 실측값에서 도출했으며, 근거가 되는 실측 수치를 같은 행에 병기했습니다.
A4: 항목 | B4: V2 점수 | C4: V3 점수 | D4: 우세 | E4: 실측 근거 (V2 → V3) | F4: 판정 사유 | G4: 신뢰도
A5: C1 완전성 | B5: 5 | C5: 3 | D5: =IF(B5>C5,"V2",IF(C5>B5,"V3","동률")) -> V2 | E5: 작성률 86.3%(82/95) → 73.7%(70/95) | F5: V3 미작성 25건은 전부 QA 차단(blocked)에 의한 의도적 공란. 품질관리는 건전하나 산출물 관점에서는 빈칸. | G5: 높음
A6: C2 항목 적합성 | B6: 5 | C6: 3 | D6: =IF(B6>C6,"V2",IF(C6>B6,"V3","동률")) -> V2 | E6: 항목 키워드 충족률 0.856 → 0.612 (V2 우세 43/65) | F6: 3문장 이상으로 길이 통제해도 0.863 → 0.723으로 격차 유지. V3는 항목이 요구한 내용을 빠뜨리는 경우가 있음(예: Q-063 다양성 현황에서 인원 수치 전면 누락). | G6: 높음
A7: C3 근거 충실성·검증가능성 | B7: 2 | C7: 5 | D7: =IF(B7>C7,"V2",IF(C7>B7,"V3","동률")) -> V3 | E7: 근거일치율 0.408 → 0.629 (V3 우세 59/65) | F7: V2는 Evidence에 없는 서술을 다수 추가. V2 자체 검토열도 Evidence 부족(Thiếu)을 64건 지적. 길이 통제(V2 앞 2문장 0.477 vs V3 전체 0.629)해도 V3 우세 유지. | G7: 높음
A8: C4 균형성 | B8: 4 | C8: 3 | D8: =IF(B8>C8,"V2",IF(C8>B8,"V3","동률")) -> V2 | E8: 리스크·과제 언급 답변 비율 59.8% → 37.1% | F8: V2가 부정·과제 서술을 더 자주 포함. 다만 V2 본문이 2.6배 길어 발생 확률이 높은 점을 감안해 격차를 1점으로만 반영. | G8: 중간
A9: C5 구체성 | B9: 5 | C9: 3 | D9: =IF(B9>C9,"V2",IF(C9>B9,"V3","동률")) -> V2 | E9: 1천자당 숫자 23.3개 → 12.8개, 연도 언급률 39.0% → 18.6% | F9: 길이로 정규화해도 V2가 약 1.8배. V3는 요약 과정에서 수치를 탈락시키는 경향. | G9: 높음
A10: C6 명확성 | B10: 4 | C10: 4 | D10: =IF(B10>C10,"V2",IF(C10>B10,"V3","동률")) -> 동률 | E10: 평균 문장 93.0자 → 94.1자, 120자 초과 장문 비율 15.6% → 18.0% | F10: 실질적 동률. 양쪽 모두 한 문장이 다소 길어 국문 보고서 권장선(60~80자)을 상회. | G10: 높음
A11: C7 문장 자연스러움·문법 무결성 | B11: 5 | C11: 2 | D11: =IF(B11>C11,"V2",IF(C11>B11,"V3","동률")) -> V2 | E11: 출처 헤지구 삽입 0건 → 24건(작성분의 34.3%), 문장 파손 0건 → 5건 | F11: V3의 "검토 중인 제안 자료상", "외부 평가 자료상"은 사람이 쓴 보고서에 등장하지 않는 파이프라인 잔여물. "외부 평가 자료상 또한," 처럼 접속을 끊고 들어가 비문을 만드는 사례 5건. | G11: 높음
A12: C8 문체 리듬 다양성(버스티니스) | B12: 4 | C12: 4 | D12: =IF(B12>C12,"V2",IF(C12>B12,"V3","동률")) -> 동률 | E12: 문장길이 CV 0.242 → 0.249 (3문장 이상 28건 기준) | F12: 전체 평균으로는 V2가 높아 보이나(0.230 vs 0.185) 이는 V3 답변이 평균 2.3문장으로 짧은 데서 온 착시. 길이를 맞추면 동률이며 오히려 V3가 근소 우위. | G12: 중간
A13: C9 상투어·템플릿 회피 | B13: 3 | C13: 4 | D13: =IF(B13>C13,"V2",IF(C13>B13,"V3","동률")) -> V3 | E13: 1천자당 상투어 5.79개 → 3.78개 (낮을수록 우수) | F13: V3가 무내용 부사·상투 술어를 덜 씀. 3문장 이상 통제 시에도 5.33 → 3.65로 V3 우세 유지. | G13: 높음
A14: C10 어휘 다양성 | B14: 4 | C14: 4 | D14: =IF(B14>C14,"V2",IF(C14>B14,"V3","동률")) -> 동률 | E14: MATTR 0.9386 → 0.9380 (V2 앞 2문장 vs V3 전체, 길이 통제) | F14: 통계적으로 무의미한 차이. 길이 미통제 시에도 0.940 vs 0.938로 동률. | G14: 높음
A16: 가중 합계 (100점 환산)
A17: 가중치A — 보고서 초안 품질 관점 | B17: =SUMPRODUCT(B5:B14,'01_평가기준'!$E$10:$E$19)/5 -> 80.8 | C17: =SUMPRODUCT(C5:C14,'01_평가기준'!$E$10:$E$19)/5 -> 70 | D17: =IF(B17>C17,"V2 우세",IF(C17>B17,"V3 우세","동률")) -> V2 우세
A18: 가중치B — 사람이 쓴 글 같은가 관점 | B18: =SUMPRODUCT(B5:B14,'01_평가기준'!$F$10:$F$19)/5 -> 83.2 | C18: =SUMPRODUCT(C5:C14,'01_평가기준'!$F$10:$F$19)/5 -> 67 | D18: =IF(B18>C18,"V2 우세",IF(C18>B18,"V3 우세","동률")) -> V2 우세
A19: 단순 평균 (가중 없음) | B19: =AVERAGE(B5:B14)*20 -> 82 | C19: =AVERAGE(C5:C14)*20 -> 70 | D19: =IF(B19>C19,"V2 우세",IF(C19>B19,"V3 우세","동률")) -> V2 우세
A20: 항목 승패 (V2승 / V3승 / 동률) | B20: =COUNTIF(D5:D14,"V2") -> 5 | C20: =COUNTIF(D5:D14,"V3") -> 2 | D20: =COUNTIF(D5:D14,"동률")&"건 동률" -> 3건 동률

Sheet 03_지표실측
A1: 실측 지표 원본 — 04_항목별비교 시트를 집계한 값
A2: 모든 수치는 04 시트를 참조하는 수식입니다. 04 시트 값이 바뀌면 여기도 함께 갱신됩니다.
A3: "양쪽 작성분(65건) 기준" = V2·V3 모두 본문이 있는 지표만 대상. 한쪽만 작성된 건은 문체 비교에서 제외해야 공정합니다.
A5: 구분 | B5: 지표 | C5: V2 | D5: V3 | E5: 우세 | F5: 해석 / 주의
A6: 규모 | B6: 작성 건수 (전체 95개 중) | C6: =SUM('04_항목별비교'!F2:F96) -> 82 | D6: =SUM('04_항목별비교'!G2:G96) -> 70 | E6: =IF(C6>D6,"V2",IF(D6>C6,"V3","동률")) -> V2 | F6: V2 82건 / V3 70건. 양쪽 모두 작성 65건, V2만 17건, V3만 5건, 둘 다 공란 8건.
A7: 규모 | B7: 평균 글자수 (양쪽 작성분) | C7: =AVERAGEIFS('04_항목별비교'!H2:H96,'04_항목별비교'!$F$2:$F$96,1,'04_항목별비교'!$G$2:$G$96,1) -> 555.23077 | D7: =AVERAGEIFS('04_항목별비교'!I2:I96,'04_항목별비교'!$F$2:$F$96,1,'04_항목별비교'!$G$2:$G$96,1) -> 215.61538 | E7: 참고 | F7: V2가 2.6배 길다. 이 길이 차이가 아래 여러 지표를 오염시키므로 길이 통제 결과를 반드시 함께 볼 것.
A8: 규모 | B8: 평균 문장수 (양쪽 작성분) | C8: =AVERAGEIFS('04_항목별비교'!J2:J96,'04_항목별비교'!$F$2:$F$96,1,'04_항목별비교'!$G$2:$G$96,1) -> 5.9076923 | D8: =AVERAGEIFS('04_항목별비교'!K2:K96,'04_항목별비교'!$F$2:$F$96,1,'04_항목별비교'!$G$2:$G$96,1) -> 2.3076923 | E8: 참고 | F8: V2 5.9문장 / V3 2.3문장. V3는 사실상 요약문 수준의 분량.
A9: 명확성 | B9: 평균 문장 길이(자) | C9: =AVERAGEIFS('04_항목별비교'!L2:L96,'04_항목별비교'!$F$2:$F$96,1,'04_항목별비교'!$G$2:$G$96,1) -> 92.989231 | D9: =AVERAGEIFS('04_항목별비교'!M2:M96,'04_항목별비교'!$F$2:$F$96,1,'04_항목별비교'!$G$2:$G$96,1) -> 94.090769 | E9: 참고 | F9: 93.0자 vs 94.1자 — 사실상 동률. 양쪽 다 국문 보고서 권장 60~80자를 넘김(공통 개선 지점).
A10: 명확성 | B10: 120자 초과 장문 비율 | C10: 0.156 | D10: 0.18 | E10: =IF(C10<D10,"V2",IF(D10<C10,"V3","동률")) -> V2 | F10: V2 60/384문장, V3 27/150문장. 근소하게 V2 우세.
A11: 문체 | B11: 문장길이 변동계수 CV (전체) | C11: =AVERAGEIFS('04_항목별비교'!N2:N96,'04_항목별비교'!$F$2:$F$96,1,'04_항목별비교'!$G$2:$G$96,1) -> 0.23001538 | D11: =AVERAGEIFS('04_항목별비교'!O2:O96,'04_항목별비교'!$F$2:$F$96,1,'04_항목별비교'!$G$2:$G$96,1) -> 0.18466154 | E11: =IF(C11>D11,"V2",IF(D11>C11,"V3","동률")) -> V2 | F11: 표면상 V2 우세(0.230 vs 0.185)이나 V3 답변이 짧아 생긴 착시.
A12: 문체 | B12: 문장길이 CV — 3문장 이상 28건만 | C12: 0.242 | D12: 0.249 | E12: =IF(C12>D12,"V2",IF(D12>C12,"V3","동률")) -> V3 | F12: ★ 길이를 맞추면 뒤집힘. 버스티니스는 사실상 동률이며 V3가 근소 우위. 전체 평균만 보면 오판하게 되는 대표 사례.
A13: 문체 | B13: MATTR 어휘다양성 (전체) | C13: =AVERAGEIFS('04_항목별비교'!P2:P96,'04_항목별비교'!$F$2:$F$96,1,'04_항목별비교'!$G$2:$G$96,1) -> 0.94024462 | D13: =AVERAGEIFS('04_항목별비교'!Q2:Q96,'04_항목별비교'!$F$2:$F$96,1,'04_항목별비교'!$G$2:$G$96,1) -> 0.93803231 | E13: =IF(C13>D13,"V2",IF(D13>C13,"V3","동률")) -> V2 | F13: 0.940 vs 0.938 — 차이 없음.
A14: 문체 | B14: MATTR — 길이 통제(V2 앞2문장 vs V3 전체) | C14: 0.9386 | D14: 0.938 | E14: 참고 | F14: 차이 0.0006 — 동률 확정. 어휘 다양성으로는 두 버전을 구분할 수 없음.
A15: 문체 | B15: 1천자당 상투어 수 | C15: =AVERAGEIFS('04_항목별비교'!V2:V96,'04_항목별비교'!$F$2:$F$96,1,'04_항목별비교'!$G$2:$G$96,1) -> 5.7872308 | D15: =AVERAGEIFS('04_항목별비교'!W2:W96,'04_항목별비교'!$F$2:$F$96,1,'04_항목별비교'!$G$2:$G$96,1) -> 3.7833846 | E15: =IF(C15<D15,"V2",IF(D15<C15,"V3","동률")) -> V3 | F15: ★ V3 우세. "지속적으로/적극적으로/체계적으로/노력하고 있습니다" 등. 3문장 이상 통제 시에도 5.33 vs 3.65로 유지.
A16: 충실성 | B16: 근거일치율 (Evidence 대비 문자 4-gram 중복) | C16: =AVERAGEIFS('04_항목별비교'!R2:R96,'04_항목별비교'!$F$2:$F$96,1,'04_항목별비교'!$G$2:$G$96,1) -> 0.40770769 | D16: =AVERAGEIFS('04_항목별비교'!S2:S96,'04_항목별비교'!$F$2:$F$96,1,'04_항목별비교'!$G$2:$G$96,1) -> 0.62856923 | E16: =IF(C16>D16,"V2",IF(D16>C16,"V3","동률")) -> V3 | F16: ★ 가장 큰 격차. V3 우세 59/65. V2는 Evidence에 없는 서술을 상당량 생성.
A17: 충실성 | B17: 근거일치율 — V2 내부: 앞2문장(C열) vs 뒤문장(D열) | C17: 0.477 | D17: 0.357 | E17: 참고 | F17: ★ V2 내부 대조이므로 C·D열은 V2/V3가 아님. 뒤로 갈수록 근거에서 멀어짐(57건 중 46건). V2의 추가 분량 상당수가 무근거 확장.
A18: 충실성 | B18: 근거 우세 판정 (V2승 / V3승) | C18: =COUNTIF('04_항목별비교'!AB2:AB96,"V2") -> 6 | D18: =COUNTIF('04_항목별비교'!AB2:AB96,"V3") -> 59 | E18: =IF(C18>D18,"V2",IF(D18>C18,"V3","동률")) -> V3 | F18: 65건 중 V3가 59건 우세.
A19: 적합성 | B19: 항목 키워드 충족률 | C19: =AVERAGEIFS('04_항목별비교'!T2:T96,'04_항목별비교'!$F$2:$F$96,1,'04_항목별비교'!$G$2:$G$96,1) -> 0.85615385 | D19: =AVERAGEIFS('04_항목별비교'!U2:U96,'04_항목별비교'!$F$2:$F$96,1,'04_항목별비교'!$G$2:$G$96,1) -> 0.61153846 | E19: =IF(C19>D19,"V2",IF(D19>C19,"V3","동률")) -> V2 | F19: ★ V2 우세. Field가 요구한 주제어를 본문이 실제로 다루는 비율.
A20: 적합성 | B20: 적합 우세 판정 (V2승 / V3승) | C20: =COUNTIF('04_항목별비교'!AC2:AC96,"V2") -> 43 | D20: =COUNTIF('04_항목별비교'!AC2:AC96,"V3") -> 5 | E20: =IF(C20>D20,"V2",IF(D20>C20,"V3","동률")) -> V2 | F20: 65건 중 V2가 43건 우세, V3 5건, 동률 17건.
A21: 구체성 | B21: 평균 숫자 출현 수 | C21: =AVERAGEIFS('04_항목별비교'!X2:X96,'04_항목별비교'!$F$2:$F$96,1,'04_항목별비교'!$G$2:$G$96,1) -> 12.923077 | D21: =AVERAGEIFS('04_항목별비교'!Y2:Y96,'04_항목별비교'!$F$2:$F$96,1,'04_항목별비교'!$G$2:$G$96,1) -> 2.7692308 | E21: =IF(C21>D21,"V2",IF(D21>C21,"V3","동률")) -> V2 | F21: V2 12.9개 / V3 2.8개. 길이로 나눠도 1천자당 23.3 vs 12.8로 V2 우세.
A22: 자연스러움 | B22: 출처 헤지구("~자료상") 총 출현 | C22: 0 | D22: =SUM('04_항목별비교'!Z2:Z96) -> 24 | E22: =IF(C22<D22,"V2",IF(D22<C22,"V3","동률")) -> V2 | F22: ★ V2 0건 / V3 24건(작성 70건의 34.3%). 사람이 쓴 보고서에 없는 표현 — 인간유사성 최대 감점 요인.
A23: 자연스러움 | B23: 문장 중간 접속 파손 건수 | C23: 0 | D23: =SUM('04_항목별비교'!AA2:AA96) -> 5 | E23: =IF(C23<D23,"V2",IF(D23<C23,"V3","동률")) -> V2 | F23: "외부 평가 자료상 또한, ~" 같이 접속을 끊고 삽입돼 비문이 된 사례. V3 5건.
A24: 균형성 | B24: 리스크·과제 언급 답변 비율 | C24: 0.598 | D24: 0.371 | E24: =IF(C24>D24,"V2",IF(D24>C24,"V3","동률")) -> V2 | F24: V2 우세이나 본문이 2.6배 길어 노출 기회가 많은 점 감안 필요.

Sheet 04_항목별비교
A1: 지표ID | B1: 필드(V2) | C1: 필드(V3) | D1: V2 본문 | E1: V3 본문 | F1: V2작성 | G1: V3작성 | H1: V2 글자수 | I1: V3 글자수 | J1: V2 문장수 | K1: V3 문장수 | L1: V2 평균문장길이 | M1: V3 평균문장길이 | N1: V2 CV | O1: V3 CV | P1: V2 MATTR | Q1: V3 MATTR | R1: V2 근거일치율 | S1: V3 근거일치율 | T1: V2 항목적합도 | U1: V3 항목적합도 | V1: V2 상투어/1천자 | W1: V3 상투어/1천자 | X1: V2 숫자수 | Y1: V3 숫자수 | Z1: V3 헤지구 | AA1: V3 접속파손 | AB1: 근거 우세 | AC1: 적합 우세 | AD1: 상태(V3)
A2: EBX-Q-001 | B2: 일반 / 전략 (Strategy) / ESG 비전 및 중장기 전략 | C2: ESG 경영 / ESG 비전 및 중장기 전략 | D2: 대웅제약은 인류와 지구의 건강을 지키는 기업이라는 ESG 비전을 수립하고, 경제적·사회적·환경적 지속가능성을 균형 있게 고려한 ESG 경영을 추진하고 있습니다. 특히 보다 강화된 윤리경영을 통해 신뢰받는 기업으로 거듭나기 위한 진보하는 윤리경영을 추진하며, ESG 체계의 고도화와 책임 있는 경영 실천을 지속적으로 강화하고 있습니다. | E2: 검토 중인 제안 자료상 대웅제약은 ‘인류와 지구의 건강을 지키는 기업’이라는 ESG 비전 아래 경제적, 사회적, 환경적 지속가능성을 균형 있게 고려한 ESG 경영을 추진하고 있습니다. ‘CARE for people and planet’ 전략을 기반으로 Cure, Advance, Respect, Earth의 4대 방향성을 설정하여 영역별 핵심 과제와 세부 실행과제를 수립하였으며, 이를 통해 ESG 체계 고도화와 책임 있는 경영 실천을 강화하고 있습니다. | F2: =IF(LEN(D2)>0,1,0) -> 1 | G2: =IF(LEN(E2)>0,1,0) -> 1 | H2: 186 | I2: 254 | J2: 2 | K2: 2 | L2: 92.5 | M2: 126.5 | N2: 0.038 | O2: 0.194 | P2: 0.9167 | Q2: 0.9676 | R2: 0.754 | S2: 0.791 | T2: 0.5 | U2: 0.75 | V2: 21.51 | W2: 11.81 | X2: 0 | Y2: 1 | Z2: 1 | AA2: 0 | AB2: =IF(AND($F2=1,$G2=1),IF(R2>S2,"V2",IF(S2>R2,"V3","동률")),"비교불가") -> V3 | AC2: =IF(AND($F2=1,$G2=1),IF(T2>U2,"V2",IF(U2>T2,"V3","동률")),"비교불가") -> V3 | AD2: Answer: passed / Consumer Decision: answered_partial / QA Grade: cautious / Publication: review_required / Publication Reason: draft_evidence / Coverage: draft_evidence / RAG Coverage: insufficient / Answerable: False / Evidence: insufficient
A3: EBX-Q-002 | B3: 일반 / 거버넌스 (Governance) / ESG 거버넌스 및 의사결정 체계 | C3: ESG 경영 / ESG 거버넌스 및 의사결정 체계 | D3: 대웅제약 이사회는 대표이사를 포함한 6인의 이사로 구성되어 있으며, 그룹사의 환경안전 경영방침과 조직현황, 활동실적, KPI, 예산 및 환경안전보건사업계획을 검토하고 승인하는 최고 의사결정기구로서의 역할을 수행합니다. 이사회는 주요 ESG 및 환경경영 현안을 보고받아 전략적 방향성을 검토하며, 이를 효율적으로 실행하기 위해 ESG위원회와 대웅그룹 EHS 경영위원회를 운영하고 있습니다. ESG위원회는 전사적인 ESG 전략과 주요 지속가능경영 이슈를 검토하고 심의하는 역할을 담당하며, 대웅그룹 EHS 경영위원회는 환경·안전·보건(EHS) 분야의 정책과 목표 및 실행과제를 수립하고 이행 현황을 점검하는 책임을 집행합니다. 또한, 사업장 단위의 환경관리 활동과 성과를 관리하고 부서 간 협업을 지원하기 위해 EHS 간사협의체를 운영함으로써 현장 중심의 관리 체계를 강화하고 있습니다. 실무 지원 및 실행 체계로는 ESG팀과 ESG TF를 구축하여 운영하고 있습니다. ESG팀은 사외이사 지원조직으로서 위원회의 원활한 운영과 ESG 안건 검토를 지원하는 역할을 수행합니다. 이와 함께 ESG TF는 영역별 실무부서와 긴밀하게 연계하여 주요 과제를 추진함으로써, ESG 경영의 가치가 조직 전반에 내재화되고 실질적인 성과로 이어질 수 있도록 통합적으로 관리하고 있습니다. 이러한 체계적인 거버넌스 구조를 통해 대웅제약은 전략 수립부터 실행, 점검에 이르는 전 과정에서 ESG 경영의 실효성을 확보하고 있습니다. | E3: 검토 중인 제안 자료상 최고 의사결정기구인 이사회는 주요 ESG 및 환경경영 현안을 보고받고 전략적 방향을 검토하며, 이사회 산하 ESG위원회는 전사 ESG 전략과 주요 지속가능경영 이슈를 검토 및 심의합니다. 대웅그룹 EHS 경영위원회는 환경 안전 보건(EHS) 분야의 정책과 목표를 수립하고 이행 현황을 점검하며, EHS 간사협의체는 사업장 단위의 환경관리 활동과 성과를 관리합니다. 실무적으로는 ESG팀이 위원회 운영 및 안건 검토를 지원하고, ESG TF가 영역별 실무부서와 연계하여 주요 과제를 추진하고 있습니다. | F3: =IF(LEN(D3)>0,1,0) -> 1 | G3: =IF(LEN(E3)>0,1,0) -> 1 | H3: 731 | I3: 292 | J3: 8 | K3: 3 | L3: 90.5 | M3: 96.7 | N3: 0.309 | O3: 0.178 | P3: 0.9344 | Q3: 0.9152 | R3: 0.528 | S3: 0.698 | T3: 1 | U3: 0.5 | V3: 4.1 | W3: 3.42 | X3: 1 | Y3: 0 | Z3: 1 | AA3: 0 | AB3: =IF(AND($F3=1,$G3=1),IF(R3>S3,"V2",IF(S3>R3,"V3","동률")),"비교불가") -> V3 | AC3: =IF(AND($F3=1,$G3=1),IF(T3>U3,"V2",IF(U3>T3,"V3","동률")),"비교불가") -> V2 | AD3: Answer: passed / Consumer Decision: answered_partial / QA Grade: cautious / Publication: review_required / Publication Reason: draft_evidence / Coverage: draft_evidence / RAG Coverage: insufficient / Answerable: False / Evidence: insufficient
A4: EBX-Q-003 | B4: 일반 / 위험 관리 (Risk Management) / ESG 리스크 식별 및 관리 체계 | C4: ESG 경영 / ESG 리스크 식별 및 관리 체계 | D4: 대웅제약은 가치사슬 전반의 지속가능성 리스크를 체계적으로 식별하고 관리하기 위해 영역별 맞춤형 대응 체계를 운영하고 있습니다. 제약·바이오 산업의 특성을 고려하여 R&D부터 원료 조달, 제조, 포장, 유통, 제품 사용 및 폐의약품 처리까지의 전 과정에서 자연과의 접점을 검토하며, 국내 주요 사업장을 중심으로 자연 관련 의존성과 영향, 리스크의 관리 우선순위를 도출하고 있습니다. 특히 환경규제, 탄소가격, 공시 요구, 극한기상, 평균기온 상승 등 주요 요인에 따른 배출량, 에너지 사용량, 검증 수준, 피해 현황 등을 지속적으로 모니터링하여 대응 실행력을 강화하고 있습니다. 공급망 리스크 관리를 위해서는 협력회사의 노동인권, 안전보건, 환경, 윤리 등 ESG 전반을 아우르는 포괄적 관리 기준을 적용하고 있습니다. 공급망 내 지속가능성 리스크를 사전에 식별하기 위해 실사 의무를 리스크 관리 체계에 통합하고, 협력회사가 자율적으로 행동규범을 이행하고 지속가능경영을 실천할 수 있도록 지원합니다. 정보보호 분야에서는 개인정보보호 고도화를 위해 17개 점검 대상을 기준으로 위험 식별 및 이행조치를 실시하고 있습니다. 주요 개인정보 처리 업무와 시스템을 대상으로 전년도 이슈와 현황을 재검토하여 미흡 항목을 발굴하고, 세부 수행계획을 통해 보호대책 이행을 지원하고 있습니다. 이를 통해 총 66개 항목 중 27개 항목의 이행조치를 완료하였으며, 나머지 39개 항목에 대해서는 현재 이행조치를 진행 중입니다. | E4: 대웅제약은 영역별 특성에 맞춘 ESG 리스크 식별 및 관리 체계를 운영하고 있습니다. 검토 중인 제안 자료상 기후변화 대응을 위해 TCFD 권고안에 따라 전환 및 물리적 리스크와 에너지 효율화 기회를 식별하고, 환경규제와 탄소가격 등 주요 요인별 관리 지표를 연계하여 모니터링하고 있습니다. 자연자본 및 생물다양성 리스크는 TNFD의 LEAP 접근법을 참고하여 가치사슬 전반의 접점을 검토하고 관리 우선순위를 도출하는 평가 절차를 수립하였습니다. 또한, 공급망 내 지속가능성 리스크를 사전에 식별하고 관리하기 위해 실사 의무를 리스크 관리 체계에 통합하고 있으며, 정보보호 분야에서는 점검 대상을 기준으로 위험 식별 및 이행조치를 실시하고 모니터링을 통해 이를 관리하고 있습니다. | F4: =IF(LEN(D4)>0,1,0) -> 1 | G4: =IF(LEN(E4)>0,1,0) -> 1 | H4: 731 | I4: 380 | J4: 8 | K4: 4 | L4: 90.5 | M4: 94.2 | N4: 0.261 | O4: 0.334 | P4: 0.9604 | Q4: 0.951 | R4: 0.56 | S4: 0.487 | T4: 1 | U4: 1 | V4: 6.84 | W4: 2.63 | X4: 8 | Y4: 0 | Z4: 1 | AA4: 0 | AB4: =IF(AND($F4=1,$G4=1),IF(R4>S4,"V2",IF(S4>R4,"V3","동률")),"비교불가") -> V2 | AC4: =IF(AND($F4=1,$G4=1),IF(T4>U4,"V2",IF(U4>T4,"V3","동률")),"비교불가") -> 동률 | AD4: Answer: passed / Consumer Decision: answered_partial / QA Grade: cautious / Publication: review_required / Publication Reason: draft_evidence / Coverage: draft_evidence / RAG Coverage: complete / Answerable: True / Evidence: high_confidence
A5: EBX-Q-004 | B5: 사회 / 전략 (Strategy) / 안전보건 정책 및 목표 | C5: 안전 보건 / 안전보건 정책 및 목표 | D5: 대웅제약은 생명존중의 가치를 경영의 최우선 순위에 두고, 모든 경영 활동에서 환경·안전·보건을 핵심 원칙으로 삼는 환경안전보건 경영방침을 수립하여 운영하고 있습니다. 국내외 환경·안전·보건 법규와 국제 협약을 엄격히 준수하며 글로벌 수준의 관리체계를 구축함으로써 법적 기준을 넘어서는 책임경영을 실천하고 있습니다. 해당 계획은 이사회의 검토와 승인을 거쳐 실행되며, EHS 경영 목표 달성을 통해 구성원과 이해관계자가 법규를 준수하는 문화를 조성하여 사업장 내 사고 예방에 주력하고 있습니다. 실행 측면에서는 2025년 목표인 무재해를 달성하였으며, 근로자 정기교육, 신규채용 시 교육, 전문인력 직무교육 등 법정 교육 이수율 100%를 기록하였습니다. 또한 생산본부를 중심으로 아차사고 제안 활동을 활발히 추진하고 있으며, 본사 최초의 안전보건 관리체계를 구축하고 있습니다. 이와 더불어 임직원 건강증진프로그램을 운영하여 질병 예방과 생산성 향상을 도모하는 등 안전과 보건 영향을 통합적으로 관리하고 있습니다. | E5: 대웅제약은 '생명존중'의 가치를 경영의 최우선 순위에 두고, 모든 경영 활동에서 환경 안전 보건을 핵심 원칙으로 삼는 환경안전보건 경영방침을 운영하고 있습니다. 이를 위해 국내외 법규와 국제 협약을 엄격히 준수하며 글로벌 수준의 관리체계를 수립 운영하는 책임경영을 실천하고 있습니다. 또한 매년 안전보건 경영 원칙 점검과 함께 안전 및 보건에 관한 계획을 수립하여 이사회의 검토와 승인을 거쳐 실행하며, 2025년에는 무재해 달성을 목표로 설정하였습니다. | F5: =IF(LEN(D5)>0,1,0) -> 1 | G5: =IF(LEN(E5)>0,1,0) -> 1 | H5: 510 | I5: 254 | J5: 6 | K5: 3 | L5: 84.2 | M5: 84 | N5: 0.124 | O5: 0.138 | P5: 0.9641 | Q5: 0.9548 | R5: 0.476 | S5: 0.571 | T5: 0.667 | U5: 0.667 | V5: 3.92 | W5: 3.94 | X5: 7 | Y5: 4 | Z5: 0 | AA5: 0 | AB5: =IF(AND($F5=1,$G5=1),IF(R5>S5,"V2",IF(S5>R5,"V3","동률")),"비교불가") -> V3 | AC5: =IF(AND($F5=1,$G5=1),IF(T5>U5,"V2",IF(U5>T5,"V3","동률")),"비교불가") -> 동률 | AD5: Answer: passed / Consumer Decision: answered / QA Grade: full / Publication: published / Publication Reason: complete_grounded_answer / Coverage: complete_grounded_answer / RAG Coverage: complete / Answerable: True / Evidence: high_confidence
A6: EBX-Q-005 | B6: 사회 / 거버넌스 (Governance) / 안전보건 관리 조직 및 책임 | C6: 안전 보건 / 안전보건 관리 조직 및 책임 | E6: 검토 중인 제안 자료상 대웅그룹은 대웅제약 대표이사가 위원장을 맡는 EHS경영위원회를 통해 환경안전보건 의사결정을 수행하며, 반기 1회 이상 그룹사별 EHS 운영 전략과 이슈 및 개선사항을 심의합니다. EHS경영위원회 산하에는 그룹사 실무 담당자로 구성된 EHS간사협의체를 운영하여 경영진의 전략을 현장에 반영하고 지표 관리 및 효과적인 관리방안을 마련하고 있습니다. | F6: =IF(LEN(D6)>0,1,0) -> 0 | G6: =IF(LEN(E6)>0,1,0) -> 1 | H6: 0 | I6: 205 | J6: 0 | K6: 2 | L6: 0 | M6: 102 | N6: 0 | O6: 0.098 | P6: 0 | Q6: 0.975 | R6: 0 | S6: 0.57 | T6: 0 | U6: 0.5 | V6: 0 | W6: 0 | X6: 0 | Y6: 1 | Z6: 1 | AA6: 0 | AB6: =IF(AND($F6=1,$G6=1),IF(R6>S6,"V2",IF(S6>R6,"V3","동률")),"비교불가") -> 비교불가 | AC6: =IF(AND($F6=1,$G6=1),IF(T6>U6,"V2",IF(U6>T6,"V3","동률")),"비교불가") -> 비교불가 | AD6: Answer: passed / Consumer Decision: answered_partial / QA Grade: cautious / Publication: review_required / Publication Reason: draft_evidence / Coverage: draft_evidence / RAG Coverage: complete / Answerable: True / Evidence: medium_confidence
A7: EBX-Q-006 | B7: 사회 / 위험 관리 (Risk Management) / 산업안전 리스크 식별 및 예방 활동 | C7: 안전 보건 / 산업안전 리스크 식별 및 예방 활동 | D7: 대웅제약은 생산활동 전반의 유해·위험요인 평가를 통해 중대성을 결정하고 감소대책을 수립함으로써 중대재해 예방과 지속경영을 추진하고 있습니다. 2025년 위험성평가를 통해 총 441건의 위험요인을 발굴하여 개선하였으며, 외주공사뿐만 아니라 내부 작업 중 위험공정이 발생할 경우 허가를 받고 작업하는 작업허가제도를 도입하여 리스크 통제를 강화하였습니다. 위험성평가 개선활동 완료 후에는 안전보건관리책임자에게 경과를 보고하며, 산업안전보건 게시판 공지 및 개인 메일링을 통해 관련 활동을 임직원과 공유하고 있습니다. 안전문화 확산을 위해 분기별 산업안전보건위원회와 매월 도급사업장 안전보건회의체를 운영하고 있으며, 이를 통해 아차사고 제안 우수사례 공유, 안전보건 시설 개선, 관리감독자 교육 등을 수행하고 있습니다. 또한 모든 구성원의 안전의식 고취를 위해 분기별 안전보건교육을 실시하고, 신규 채용 시 배치 전 안전보건교육을 온라인 또는 집체교육 형태로 제공하여 사고 예방 체계를 구축하였습니다. 예측 불가능한 비상사태에 대비하여 화재, 누출, 누유, 자연재해 및 정전 등을 사전에 예방하고 신속하게 대응하기 위한 비상대응 체제를 운영하고 있습니다. 정기적인 비상대응 교육과 훈련을 통해 실질적인 대응 방안을 습득하고 체계를 확립하고 있으며, 모든 부상 및 사고 조사 보고서와 해결 기록을 보관하여 관리합니다. 아울러 안전 및 보건 문제가 완전히 해결될 때까지 노동자를 안전하게 보호하기 위한 조치를 취하며, 측정 가능한 정책과 목표를 수립하여 지속적으로 모니터링하고 있습니다. | E7: 대웅제약은 생산활동 전반의 유해 위험요인 평가를 통해 중대성을 결정하고 감소대책을 수립 및 이행함으로써 중대재해 예방 활동을 수행하고 있으며, 2025년 위험성평가를 통해 441건의 요인을 발굴하여 개선하였습니다. 특히 외주공사뿐만 아니라 내부 작업 중 위험공정 발생 시 허가를 받는 작업허가제도를 도입하였으며, 안전 보건 화학물질 분야 전문가를 통해 현장 내 유해위험요인을 도출하고 있습니다. 또한 화재, 누출, 자연재해 및 정전 등에 대비한 비상대응 체제를 구축하여 위기상황 유형별 매뉴얼을 운영하고 정기적인 교육과 훈련을 실시하고 있습니다. 이 외에도 분기별 안전보건교육, 산업안전보건위원회 및 도급사업장 안전보건회의체 운영, 팀별 안전보건 수칙 배포 등을 통해 안전의식을 확산하고 사고를 예방하고 있습니다. | F7: =IF(LEN(D7)>0,1,0) -> 1 | G7: =IF(LEN(E7)>0,1,0) -> 1 | H7: 770 | I7: 399 | J7: 8 | K7: 4 | L7: 95.4 | M7: 99 | N7: 0.13 | O7: 0.13 | P7: 0.9633 | Q7: 0.97 | R7: 0.544 | S7: 0.562 | T7: 0.8 | U7: 0.6 | V7: 5.19 | W7: 2.51 | X7: 7 | Y7: 7 | Z7: 0 | AA7: 0 | AB7: =IF(AND($F7=1,$G7=1),IF(R7>S7,"V2",IF(S7>R7,"V3","동률")),"비교불가") -> V3 | AC7: =IF(AND($F7=1,$G7=1),IF(T7>U7,"V2",IF(U7>T7,"V3","동률")),"비교불가") -> V2 | AD7: Answer: passed / Consumer Decision: answered_partial / QA Grade: partial / Publication: review_required / Publication Reason: missing_expected_facets / Coverage: missing_expected_facets / RAG Coverage: complete / Answerable: True / Evidence: high_confidence
A8: EBX-Q-007 | B8: 사회 / 지표 (Metrics) / 산업재해 발생 현황 및 안전 성과 지표 | C8: 안전 보건 / 산업재해 발생 현황 및 안전 성과 지표 | D8: 대웅제약은 사업장 내 잠재적 위험 요인을 선제적으로 발굴하고 제거하여 임직원이 안심하고 근무할 수 있는 안전한 작업 환경을 조성하는 데 역량을 집중하고 있습니다. 현장의 실질적인 위험 관리를 위해 위험성평가를 체계적으로 실시하고 있으며, 2025년에는 이를 통해 총 441건의 위험 요인을 발굴하고 개선함으로써 사고 예방 체계를 강화하였습니다. 공정 안전 관리의 실효성을 높이기 위해 대웅제약 생산본부에서는 작업허가제도를 도입하여 운영하고 있습니다. 해당 제도는 기존의 외주공사뿐만 아니라 내부 작업 중 위험공정이 발생하는 경우에도 반드시 사전 허가를 득한 후 작업을 수행하도록 규정하여, 고위험 작업 시 발생할 수 있는 안전사고를 원천적으로 차단하는 데 기여하고 있습니다. 이러한 예방 중심의 안전보건 관리 활동을 통해 산업재해 발생 현황을 면밀히 관리하고 있습니다. 2025년 기준 산업재해 발생비율은 0.03%를 기록하였으며, 재해자 수는 1명으로 집계되었습니다. 이는 2024년의 발생비율 0.07%와 재해자 수 2명과 비교하여 감소한 수치입니다. 또한, 2023년에 1명이 발생했던 업무상 질병의 경우 2024년과 2025년에는 발생 사례가 없는 것으로 확인되어 보건 관리 측면에서도 안정적인 성과를 유지하고 있습니다. | E8: 대웅그룹은 모든 구성원의 안전의식 고취와 사고 예방을 위해 분기별 안전보건교육 및 채용 시 배치 전 안전보건교육을 실시하고 있으며, 생산본부에서는 사고 발생 및 고위험 작업 부서를 대상으로 맞춤형 특성화 교육을 추진하고 있습니다. | F8: =IF(LEN(D8)>0,1,0) -> 1 | G8: =IF(LEN(E8)>0,1,0) -> 1 | H8: 631 | I8: 128 | J8: 8 | K8: 1 | L8: 78 | M8: 128 | N8: 0.344 | O8: 0 | P8: 0.9464 | Q8: 0.9355 | R8: 0.187 | S8: 0.456 | T8: 0.833 | U8: 0.333 | V8: 3.17 | W8: 7.81 | X8: 36 | Y8: 0 | Z8: 0 | AA8: 0 | AB8: =IF(AND($F8=1,$G8=1),IF(R8>S8,"V2",IF(S8>R8,"V3","동률")),"비교불가") -> V3 | AC8: =IF(AND($F8=1,$G8=1),IF(T8>U8,"V2",IF(U8>T8,"V3","동률")),"비교불가") -> V2 | AD8: Answer: passed / Consumer Decision: answered / QA Grade: full / Publication: published / Publication Reason: complete_grounded_answer / Coverage: complete_grounded_answer / RAG Coverage: complete / Answerable: True / Evidence: high_confidence
A9: EBX-Q-008 | B9: 사회 / 전략 (Strategy) / 인권경영 정책 및 목표 | C9: 노동 및 인권 / 인권경영 정책 및 목표 | D9: 대웅제약은 사업관리와 경영 전반에서 임직원을 포함한 모든 이해관계자의 인권을 존중하기 위해 인권경영을 추진하고 있습니다. 이사회 주관으로 인권경영 원칙과 이사회 규정 조항을 정비하고 공유하며, 국내외 인권 원칙을 반영한 인권경영 정책을 수립하여 인권 보호를 실천하고 있습니다. 특히 인권 침해 리스크를 사전에 진단하고 관리할 수 있도록 이사회 차원에서 관련 정책과 규정을 지속적으로 보완하고 있으며, 본사 사업장을 대상으로 인권영향평가를 실시하여 리스크 관리 체계를 운영하고 있습니다. 인권경영의 구체적인 실천을 위해 Great Place To Work 인권경영정책 9대 원칙을 수립하였습니다. 해당 원칙에는 차별금지, 아동노동착취 금지, 근로조건 준수, 결사 및 단체교섭의 자유, 인도적 대우, 산업안정 보장, 강제노동 금지, 지역주민 인권보호, 고객의 인권보호가 포함됩니다. 또한, 인권경영의 단계적 고도화를 위해 2030년까지의 중장기 목표를 설정하여 추진하고 있습니다. 2026년까지 인권경영 확대, 2028년까지 시스템 내재화, 2030년까지 인권경영 고도화를 달성한다는 방향성을 가지고 있습니다. 이를 위해 매년 인권영향평가와 임직원 만족도 조사를 실시하고 있으며, 향후 인권영향평가 범위를 전 사업장 및 핵심 협력업체까지 확대하고 최종 준수율 80% 도달을 목표로 하고 있습니다. 아울러 임직원 다양성 교육의 자발적 이수율을 50% 이상으로 유지하며 인권 존중 문화를 확산시키고 있습니다. | E9: 대웅제약은 국내외 인권 원칙을 반영한 인권경영 정책을 수립하여 임직원을 포함한 모든 이해관계자의 인권 존중을 실천하고 있습니다. 인권경영 정책의 9대 원칙으로는 차별금지, 아동노동착취 금지, 근로조건 준수, 결사 및 단체교섭의 자유, 인도적 대우, 산업안정 보장, 강제노동 금지, 지역주민 인권보호, 고객의 인권보호가 포함됩니다. 또한 2030년까지 인권경영 확대, 시스템 내재화, 고도화를 중장기 목표로 설정하고, 매년 인권영향평가 실시 및 핵심 협력업체까지 평가 범위를 확대하는 등의 세부 계획을 추진하고 있습니다. | F9: =IF(LEN(D9)>0,1,0) -> 1 | G9: =IF(LEN(E9)>0,1,0) -> 1 | H9: 728 | I9: 290 | J9: 9 | K9: 3 | L9: 80 | M9: 96 | N9: 0.265 | O9: 0.187 | P9: 0.9368 | Q9: 0.943 | R9: 0.512 | S9: 0.564 | T9: 1 | U9: 1 | V9: 8.24 | W9: 6.9 | X9: 21 | Y9: 5 | Z9: 0 | AA9: 0 | AB9: =IF(AND($F9=1,$G9=1),IF(R9>S9,"V2",IF(S9>R9,"V3","동률")),"비교불가") -> V3 | AC9: =IF(AND($F9=1,$G9=1),IF(T9>U9,"V2",IF(U9>T9,"V3","동률")),"비교불가") -> 동률 | AD9: Answer: passed / Consumer Decision: answered / QA Grade: full / Publication: published / Publication Reason: complete_grounded_answer / Coverage: complete_grounded_answer / RAG Coverage: complete / Answerable: True / Evidence: high_confidence
A10: EBX-Q-009 | B10: 사회 / 거버넌스 (Governance) / 노동 및 인권 관리 체계 | C10: 노동 및 인권 / 노동 및 인권 관리 체계 | D10: 이사회는 인권경영 원칙과 이사회 규정 조항을 정비하고 공유함으로써 인권 보호를 위한 거버넌스 기반을 공고히 하고 있으며, 국내외 인권 원칙을 충실히 반영한 인권경영 정책을 수립하여 운영하고 있습니다. 대웅제약은 임직원을 비롯한 모든 이해관계자의 인권을 존중하는 문화를 조성하기 위해 인권경영 정책을 체계적으로 실행하고 있으며, 특히 본사 사업장을 대상으로 인권영향평가를 실시하여 잠재적인 인권 리스크를 선제적으로 진단하고 관리할 수 있는 운영 체계를 마련하였습니다. 인권경영의 실질적인 이행과 권익 보호를 위해 사내 직장 내 괴롭힘 등 내부 인권 관련 고충 처리를 전담하는 '신문고' 조직을 운영하고 있습니다. 해당 채널은 인사부서인 인사쉐어드2팀 담당자를 통해 접수 및 관리되며, 이를 통해 임직원이 겪는 인권 침해 요소를 신속하게 파악하고 대응하고 있습니다. 이와 더불어 노동조합 및 한마음협의회, 다양한 임직원 고충 처리 채널을 가동하여 구성원들의 의견을 적극적으로 경청하고 있으며, 접수된 모든 의견과 요청 사항은 사내 규정과 방침에 따라 엄격하게 조치하여 신뢰받는 노사 관계를 구축하고 있습니다. 또한 강제노동 및 인신매매 금지를 위한 공개적인 약속과 함께 이를 뒷받침하는 구체적인 정책과 절차를 보유하고 있으며, 회사의 활동으로 인해 인권에 부정적인 영향을 받은 대상자가 있을 경우 이를 해결하기 위한 구제 절차를 제공하여 책임 있는 경영을 실천하고 있습니다. 이러한 인권경영 활동의 성과는 공식 홈페이지와 언론 보도 등 다양한 공개 채널을 통해 투명하게 소통하고 있으며, 글로벌 ESG 인권경영 인증 수상 등을 통해 대외적으로도 인권 보호 체계의 우수성을 인정받고 있습니다. | E10: 대웅제약은 임직원과 이해관계자의 인권 존중을 위해 인권경영 정책을 수립하여 운영하고 있습니다. 본사 사업장에서 인권영향평가를 실시함으로써 인권 리스크를 진단하고 관리할 수 있는 체계를 마련하고 있으며, 이사회 차원에서 관련 정책과 규정을 지속적으로 보완하고 있습니다. | F10: =IF(LEN(D10)>0,1,0) -> 1 | G10: =IF(LEN(E10)>0,1,0) -> 1 | H10: 832 | I10: 149 | J10: 7 | K10: 2 | L10: 118 | M10: 74 | N10: 0.221 | O10: 0.297 | P10: 0.9484 | Q10: 0.9375 | R10: 0.375 | S10: 0.706 | T10: 1 | U10: 0.75 | V10: 7.21 | W10: 13.42 | X10: 1 | Y10: 0 | Z10: 0 | AA10: 0 | AB10: =IF(AND($F10=1,$G10=1),IF(R10>S10,"V2",IF(S10>R10,"V3","동률")),"비교불가") -> V3 | AC10: =IF(AND($F10=1,$G10=1),IF(T10>U10,"V2",IF(U10>T10,"V3","동률")),"비교불가") -> V2 | AD10: Answer: passed / Consumer Decision: answered_partial / QA Grade: partial / Publication: review_required / Publication Reason: missing_expected_facets / Coverage: missing_expected_facets / RAG Coverage: insufficient / Answerable: False / Evidence: insufficient
A11: EBX-Q-010 | B11: 사회 / 위험 관리 (Risk Management) / 인권 리스크 식별 및 대응 활동 | C11: 노동 및 인권 / 인권 리스크 식별 및 대응 활동 | F11: =IF(LEN(D11)>0,1,0) -> 0 | G11: =IF(LEN(E11)>0,1,0) -> 0 | H11: 0 | I11: 0 | J11: 0 | K11: 0 | L11: 0 | M11: 0 | N11: 0 | O11: 0 | P11: 0 | Q11: 0 | R11: 0 | S11: 0 | T11: 0 | U11: 0 | V11: 0 | W11: 0 | X11: 0 | Y11: 0 | Z11: 0 | AA11: 0 | AB11: =IF(AND($F11=1,$G11=1),IF(R11>S11,"V2",IF(S11>R11,"V3","동률")),"비교불가") -> 비교불가 | AC11: =IF(AND($F11=1,$G11=1),IF(T11>U11,"V2",IF(U11>T11,"V3","동률")),"비교불가") -> 비교불가 | AD11: Answer: failed / Consumer Decision: blocked_api_status / QA Grade: failed / Publication: blocked / Publication Reason: qa_not_passed / Coverage: writer_empty / RAG Coverage: insufficient / Answerable: False / Evidence: insufficient
A12: EBX-Q-011 | B12: 사회 / 지표 (Metrics) / 인권 관련 고충 및 처리 현황 | C12: 노동 및 인권 / 인권 관련 고충 및 처리 현황 | D12: 대웅제약은 협력적인 노사소통 활성화를 통해 내부 이해관계자의 인권을 보호하고 고충을 해결하는 체계를 운영하고 있습니다. 2025년 기준 내부 이해관계자로부터 접수된 인권 관련 고충 처리 건수는 총 63건이며, 접수된 모든 건에 대해 처리를 완료하여 인권 보호 및 고충 해결을 위한 실효성 있는 관리 성과를 거두었습니다. | F12: =IF(LEN(D12)>0,1,0) -> 1 | G12: =IF(LEN(E12)>0,1,0) -> 0 | H12: 178 | I12: 0 | J12: 2 | K12: 0 | L12: 88.5 | M12: 0 | N12: 0.254 | O12: 0 | P12: 0.9 | Q12: 0 | R12: 0.119 | S12: 0 | T12: 0.8 | U12: 0 | V12: 5.62 | W12: 0 | X12: 6 | Y12: 0 | Z12: 0 | AA12: 0 | AB12: =IF(AND($F12=1,$G12=1),IF(R12>S12,"V2",IF(S12>R12,"V3","동률")),"비교불가") -> 비교불가 | AC12: =IF(AND($F12=1,$G12=1),IF(T12>U12,"V2",IF(U12>T12,"V3","동률")),"비교불가") -> 비교불가 | AD12: Answer: empty / Consumer Decision: blocked_qa / QA Grade: failed / Publication: blocked / Publication Reason: qa_not_passed / Coverage: writer_empty / RAG Coverage: complete / Answerable: True / Evidence: high_confidence
A13: EBX-Q-012 | B13: 사회 / 전략 (Strategy) / 제품 안전 및 품질 관리 정책 | C13: 제품 안전 / 제품 안전 및 품질 관리 정책 | D13: 대웅제약은 소비자에게 안전한 제품과 일관된 서비스를 제공하는 것을 최우선 가치로 삼아 체계적인 품질 관리 시스템을 구축하고 이를 주기적으로 점검하고 있습니다. 특히 소비자 권리 보호를 실현하기 위해 구체적이고 측정 가능하며 달성 가능한 정책과 목표를 수립하고, 이를 기반으로 한 지속적인 모니터링 체계를 운영하며 품질 경영의 실효성을 높이고 있습니다. 제품의 안전성과 품질을 확보하기 위해 소비자 권리 보호에 영향을 미칠 수 있는 실체적 또는 잠재적 리스크를 정기적으로 평가하고 있으며, 이러한 평가 결과를 바탕으로 품질 관리 프로세스를 지속적으로 개선하고 있습니다. 또한, 전 임직원을 대상으로 소비자 권리 보호를 위한 전문 교육과 인식 제고 활동을 제공함으로써, 모든 구성원이 제품 안전의 중요성을 깊이 인식하고 실무에 적용할 수 있는 전사적 품질 문화를 조성하고 있습니다. 더불어 소비자 안전사고 발생 시 신속하고 정확하게 대응할 수 있는 전용 체계를 구축하여 운영함으로써, 잠재적인 리스크를 최소화하고 소비자 안전을 최우선으로 확보하는 데 주력하고 있습니다. 이러한 통합적인 품질 관리 정책과 실행 체계를 통해 제품의 설계부터 사후 관리 단계까지 엄격한 기준을 적용하며, 소비자 신뢰를 바탕으로 한 지속 가능한 헬스케어 가치를 창출하고 있습니다. | E13: 대웅제약은 소비자에게 안전한 제품과 일관된 서비스를 제공하기 위해 품질 관리 시스템을 구축하고 이를 주기적으로 점검하고 있습니다. 또한 소비자 권리 보호를 위해 구체적이고 측정 가능하며 달성 가능한 정책 및 목표를 수립하여 모니터링하고 있으며, 임직원을 대상으로 관련 교육과 인식 제고 활동을 제공하고 소비자 권리 보호에 미치는 실체적 또는 잠재적 영향을 정기적으로 평가하고 있습니다. | F13: =IF(LEN(D13)>0,1,0) -> 1 | G13: =IF(LEN(E13)>0,1,0) -> 1 | H13: 645 | I13: 215 | J13: 6 | K13: 2 | L13: 106.7 | M13: 107 | N13: 0.097 | O13: 0.327 | P13: 0.9351 | Q13: 0.9375 | R13: 0.23 | S13: 0.55 | T13: 1 | U13: 1 | V13: 4.65 | W13: 0 | X13: 0 | Y13: 0 | Z13: 0 | AA13: 0 | AB13: =IF(AND($F13=1,$G13=1),IF(R13>S13,"V2",IF(S13>R13,"V3","동률")),"비교불가") -> V3 | AC13: =IF(AND($F13=1,$G13=1),IF(T13>U13,"V2",IF(U13>T13,"V3","동률")),"비교불가") -> 동률 | AD13: Answer: passed / Consumer Decision: answered_partial / QA Grade: partial / Publication: review_required / Publication Reason: partial_answer / Coverage: partial_answer / RAG Coverage: insufficient / Answerable: False / Evidence: insufficient
A14: EBX-Q-013 | B14: 사회 / 거버넌스 (Governance) / 품질 관리 조직 및 책임 | C14: 제품 안전 / 품질 관리 조직 및 책임 | D14: 품질경영(QM), 품질보증(QA), 품질관리(QC) 조직은 상호 유기적인 협업 체계를 구축하여 안전하고 높은 품질의 제품 생산을 위한 전방위적인 관리 책임을 수행하고 있습니다. 특히 QA, 콜센터, 학술팀 등 이상사례 수집과 밀접한 관련이 있는 유관부서를 대상으로는 Advanced Pharmacovigilance(PV) 교육을 별도로 제공하여 제품 안전 관리의 전문성을 제고하고 있습니다. 제품의 안전성 확보를 위해 대웅제약이 생산하는 모든 제품의 전 생애주기에 걸쳐 이상사례와 안전성 문제를 과학적으로 탐지하고 평가하는 약물감시 활동을 전개하고 있습니다. 이를 위해 RMP, 재평가, 보고, 재심사, 사용권고 등의 제도를 통해 관리 체계를 지속적으로 강화하고 있으며, 글로벌 규제 보고 의무를 엄격히 준수하여 제품의 유익성을 평가하고 있습니다. 안전성 정보 수집 체계는 홈페이지 내 이상사례 보고 시스템을 중심으로 자발적 보고, 문헌, 임상연구, 해외사례 등 다양한 경로를 통해 다각도로 운영됩니다. 수집된 정보는 시판 전후의 안전성 시험 및 분석법 검증 과정을 거쳐 데이터의 신뢰성을 확보하고 있습니다. 또한, 품질 관리의 효율성과 정확성을 높이기 위해 품질경영시스템(QMS)을 비롯하여 전자문서관리시스템(EDMS), 실험실정보관리시스템(LIMS), 생산관리시스템(MES) 등 고도화된 디지털 시스템을 도입하여 운영함으로써 체계적인 품질 관리 환경을 구현하고 있습니다. | E14: 대웅제약은 품질경영(QM), 품질보증(QA), 품질관리(QC) 부서 간의 유기적인 협업을 통해 제품의 안전성과 고품질을 관리하고 있습니다. 품질경영(QM)팀은 그룹 전체의 품질정책 수립, 품질 기획 및 개선 활동을 주도하며 최신 GMP 가이드라인과 규정을 적용하여 글로벌 진출을 지원합니다. 품질보증(QA) 및 품질관리(QC) 조직은 SOP 문서화, 밸리데이션, 환경 및 공정관리, 시험 및 감사 업무를 수행하며, 전 임직원을 대상으로 GMP 및 PV 교육을 제공하여 품질 역량을 강화하고 있습니다. | F14: =IF(LEN(D14)>0,1,0) -> 1 | G14: =IF(LEN(E14)>0,1,0) -> 1 | H14: 713 | I14: 279 | J14: 7 | K14: 3 | L14: 101 | M14: 92.3 | N14: 0.256 | O14: 0.184 | P14: 0.9405 | Q14: 0.9098 | R14: 0.423 | S14: 0.621 | T14: 1 | U14: 0.75 | V14: 7.01 | W14: 3.58 | X14: 0 | Y14: 0 | Z14: 0 | AA14: 0 | AB14: =IF(AND($F14=1,$G14=1),IF(R14>S14,"V2",IF(S14>R14,"V3","동률")),"비교불가") -> V3 | AC14: =IF(AND($F14=1,$G14=1),IF(T14>U14,"V2",IF(U14>T14,"V3","동률")),"비교불가") -> V2 | AD14: Answer: passed / Consumer Decision: answered_partial / QA Grade: partial / Publication: review_required / Publication Reason: missing_expected_facets / Coverage: missing_expected_facets / RAG Coverage: insufficient / Answerable: False / Evidence: insufficient
A15: EBX-Q-014 | B15: 사회 / 위험 관리 (Risk Management) / 제품 품질 및 안전 리스크 관리 | C15: 제품 안전 / 제품 품질 및 안전 리스크 관리 | D15: 대웅제약은 사업 운영 전반에서 발생할 수 있는 잠재적 리스크를 효율적으로 관리하고 안정적인 사업 영위를 지속하기 위해 체계적인 운영 리스크 관리 시스템을 구축하여 운영하고 있습니다. 특히 제품 및 서비스 품질과 관련된 리스크를 선제적으로 제어하고자 품질경영시스템과 스마트 공정 운영을 도입하였으며, 이를 통해 품질 및 공정 관리 전반의 안전성을 확보하고 리스크를 정밀하게 관리하고 있습니다. 리스크 관리의 실효성을 높이기 위해 주요 부서들은 관련 법규의 변화를 지속적으로 모니터링하고 있으며, 이에 따라 내부통제 정책 전반을 개선하고 보완하는 활동을 통해 리스크 대응 역량을 강화하고 있습니다. 또한 소비자 권리 보호를 최우선 가치로 삼아 구체적이고 측정 가능하며 달성 가능한 정책과 목표를 수립하여 이를 상시 모니터링하는 체계를 가동하고 있습니다. 소비자 안전사고 발생 시에는 신속하고 정확하게 대응할 수 있는 전용 체계를 갖추어 운영함으로써 고객의 안전을 보장하고 피해를 최소화하는 데 주력하고 있습니다. 아울러 제품의 설계부터 폐기까지 이르는 생애주기 전반에 걸쳐 지속가능성과 친환경성을 통합적으로 고려하여 반영하고 있으며, 해당 요소들을 정기적으로 측정하고 관리함으로써 제품 안전성과 환경적 책임 경영을 동시에 실현하고 있습니다. | E15: 대웅제약은 품질경영시스템 및 스마트 공정 운영을 통해 제품 및 서비스 품질 관련 리스크를 관리하고 있습니다. 또한, 주요 부서들은 관련 법규의 변화에 따라 내부통제 정책 전반을 지속적으로 개선하고 보완함으로써 사업 운영 전반의 리스크를 효율적으로 관리하고 안정적인 사업 영위를 위한 시스템을 구축하여 운영하고 있습니다. | F15: =IF(LEN(D15)>0,1,0) -> 1 | G15: =IF(LEN(E15)>0,1,0) -> 1 | H15: 636 | I15: 178 | J15: 6 | K15: 2 | L15: 105.2 | M15: 88.5 | N15: 0.142 | O15: 0.322 | P15: 0.9407 | Q15: 0.8667 | R15: 0.31 | S15: 0.69 | T15: 1 | U15: 0.8 | V15: 4.72 | W15: 11.24 | X15: 0 | Y15: 0 | Z15: 0 | AA15: 0 | AB15: =IF(AND($F15=1,$G15=1),IF(R15>S15,"V2",IF(S15>R15,"V3","동률")),"비교불가") -> V3 | AC15: =IF(AND($F15=1,$G15=1),IF(T15>U15,"V2",IF(U15>T15,"V3","동률")),"비교불가") -> V2 | AD15: Answer: passed / Consumer Decision: answered_partial / QA Grade: partial / Publication: review_required / Publication Reason: missing_expected_facets / Coverage: missing_expected_facets / RAG Coverage: complete / Answerable: True / Evidence: high_confidence
A16: EBX-Q-015 | B16: 사회 / 지표 (Metrics) / 제품 안전 및 품질 관련 사고 현황 | C16: 제품 안전 / 제품 안전 및 품질 관련 사고 현황 | F16: =IF(LEN(D16)>0,1,0) -> 0 | G16: =IF(LEN(E16)>0,1,0) -> 0 | H16: 0 | I16: 0 | J16: 0 | K16: 0 | L16: 0 | M16: 0 | N16: 0 | O16: 0 | P16: 0 | Q16: 0 | R16: 0 | S16: 0 | T16: 0 | U16: 0 | V16: 0 | W16: 0 | X16: 0 | Y16: 0 | Z16: 0 | AA16: 0 | AB16: =IF(AND($F16=1,$G16=1),IF(R16>S16,"V2",IF(S16>R16,"V3","동률")),"비교불가") -> 비교불가 | AC16: =IF(AND($F16=1,$G16=1),IF(T16>U16,"V2",IF(U16>T16,"V3","동률")),"비교불가") -> 비교불가 | AD16: Answer: failed / Consumer Decision: blocked_qa / QA Grade: failed / Publication: blocked / Publication Reason: qa_not_passed / Coverage: writer_empty / RAG Coverage: complete / Answerable: True / Evidence: high_confidence
A17: EBX-Q-016 | B17: 사회 / 전략 (Strategy) / 정보보안 및 개인정보 보호 정책 | C17: 정보보호 / 정보보안 및 개인정보 보호 정책 | D17: 디지털 전환의 가속화로 정보보안 및 정보보호의 중요성이 증대됨에 따라, 대웅제약은 글로벌 수준의 강력한 보안 체계를 지속적으로 강화하고 있습니다. 이를 위해 정보보호 정책을 제정하고 매년 1회 이상 개정을 실시함으로써 최신 보안 위협에 기민하게 대응하고 전사적인 보안 역량을 고도화하고 있습니다. 특히 법무자문을 통해 1개의 정책, 3개의 규정, 12개의 지침으로 구성된 체계적인 정보보호 정책 체계를 재정비하여 데이터 보호를 위한 관리 기준과 원칙을 명확히 수립하였습니다. 이러한 정보보호 정책은 내부 임직원뿐만 아니라 관계사 및 협력사 등 업무와 관련된 모든 이해관계자에게 공유하고 있으며, 정책 준수를 권고함으로써 공급망 전반의 보안 수준을 상향 평준화하는 데 주력하고 있습니다. 또한 기술적 방어 체계 구축에 그치지 않고 보안 캠페인, 공지, 정기 교육 등 임직원의 보안 인식을 제고하기 위한 다각적인 활동을 전개하여 인적 보안 리스크를 최소화하고 있습니다. 이와 함께 내부 정보 유출을 비롯한 이상 행위를 실시간으로 탐지하기 위한 모니터링 시스템을 상시 운영함으로써, 정책적 기준과 기술적 통제가 조화를 이루는 통합 보안 관리 체계를 공고히 하고 있습니다. 대웅제약은 이러한 다층적인 보안 전략을 통해 기업의 핵심 자산과 개인정보를 안전하게 보호하며 신뢰받는 디지털 환경을 조성하고 있습니다. | E17: 대웅제약은 1개의 정책, 3개의 규정, 12개의 지침으로 구성된 정보보호 정책 체계를 법무자문을 통해 재정비하였으며, 매년 1회 이상 개정을 통해 보안 역량을 강화하고 있습니다. 임직원, 관계사, 협력사 등 모든 이해관계자에게 해당 정책을 공유하고 준수를 권고하며, 해외 파트너사를 대상으로 보안 교육과 감사를 실시하여 정보 유출을 예방하고 있습니다. 또한, ISO 27001(정보보안관리 시스템) 및 ISO 27701(개인정보보호 경영 시스템) 국제 표준 인증을 유지하여 정보 자산과 고객 개인정보를 보호하고 있으며, 전문 모니터링 시스템을 통해 내부 정보 유출 및 이상 행위에 선제적으로 대응하고 있습니다. | F17: =IF(LEN(D17)>0,1,0) -> 1 | G17: =IF(LEN(E17)>0,1,0) -> 1 | H17: 672 | I17: 341 | J17: 7 | K17: 3 | L17: 95.1 | M17: 113 | N17: 0.155 | O17: 0.194 | P17: 0.9331 | Q17: 0.9125 | R17: 0.388 | S17: 0.698 | T17: 1 | U17: 1 | V17: 4.46 | W17: 2.93 | X17: 5 | Y17: 15 | Z17: 0 | AA17: 0 | AB17: =IF(AND($F17=1,$G17=1),IF(R17>S17,"V2",IF(S17>R17,"V3","동률")),"비교불가") -> V3 | AC17: =IF(AND($F17=1,$G17=1),IF(T17>U17,"V2",IF(U17>T17,"V3","동률")),"비교불가") -> 동률 | AD17: Answer: passed / Consumer Decision: answered / QA Grade: full / Publication: published / Publication Reason: complete_grounded_answer / Coverage: complete_grounded_answer / RAG Coverage: complete / Answerable: True / Evidence: high_confidence
A18: EBX-Q-017 | B18: 사회 / 거버넌스 (Governance) / 정보보호 관리 조직 | C18: 정보보호 / 정보보호 관리 조직 | D18: 준법경영본부 정보보호팀이 대웅제약의 정보보호 업무를 전담하여 운영하고 있습니다. 전사적인 정보보호 강화를 위해 조직적, 인적, 물리적, 기술적 통제 영역 전반에서 회사 기밀정보와 개인정보보호 시스템을 종합적으로 분석하고 있으며, 이를 바탕으로 체계적인 개선 로드맵을 수립하여 이행하고 있습니다. 정보보안 및 정보보호 규정은 감독 및 규제 당국의 지침과 변화하는 업무 환경을 반영하여 매년 최소 한 차례 개정하며, 정보보호위원회의 검토와 최고경영자의 승인을 거쳐 공개하는 체계를 갖추고 있습니다. 특히 산업통상자원부가 지정한 국가핵심기술인 '보툴리눔 톡신 제제 생산기술'을 보유함에 따라, '국가핵심기술 보호관리 지침'을 제정하여 전문적인 산업보안 관리체계를 운영 중입니다. 또한 대웅 관계사에 쉐어드 서비스를 제공함으로써 그룹사 보안 전략 수립을 지원하고 관리를 수행하며, 그룹 전체가 대웅제약과 동일한 수준의 정보보안 관리체계를 유지할 수 있도록 지원하고 있습니다. 이러한 관리 체계는 해외 제조소인 '셀라톡스'의 보안관리체계 기준 정립으로 확대되어, 해외 법인의 국가핵심기술 보호 성과로 이어지고 있습니다. | E18: 대웅제약의 정보보호 업무는 준법경영본부 정보보호팀에서 전담하고 있으며, 조직적, 인적, 물리적, 기술적 통제 영역에 걸쳐 기밀정보 및 개인정보보호 시스템을 분석하고 개선 로드맵을 수립하여 이행하고 있습니다. 또한 정보보안 및 정보보호 규정은 매년 최소 한 차례 개정하며, 정보보호위원회의 검토와 최고경영자의 승인을 거쳐 공개하는 관리 체계를 운영하고 있습니다. 아울러 대웅 관계사에 쉐어드 서비스를 제공하여 그룹사 보안 전략 수립을 지원하고 동일한 수준의 정보보안 관리체계를 운영할 수 있도록 지원하고 있습니다. | F18: =IF(LEN(D18)>0,1,0) -> 1 | G18: =IF(LEN(E18)>0,1,0) -> 1 | H18: 565 | I18: 286 | J18: 6 | K18: 3 | L18: 93.3 | M18: 94.7 | N18: 0.272 | O18: 0.152 | P18: 0.9561 | Q18: 0.952 | R18: 0.6 | S18: 0.718 | T18: 1 | U18: 1 | V18: 3.54 | W18: 3.5 | X18: 0 | Y18: 0 | Z18: 0 | AA18: 0 | AB18: =IF(AND($F18=1,$G18=1),IF(R18>S18,"V2",IF(S18>R18,"V3","동률")),"비교불가") -> V3 | AC18: =IF(AND($F18=1,$G18=1),IF(T18>U18,"V2",IF(U18>T18,"V3","동률")),"비교불가") -> 동률 | AD18: Answer: passed / Consumer Decision: answered_partial / QA Grade: partial / Publication: review_required / Publication Reason: partial_answer / Coverage: partial_answer / RAG Coverage: insufficient / Answerable: False / Evidence: insufficient
A19: EBX-Q-018 | B19: 사회 / 위험 관리 (Risk Management) / 정보보안 및 개인정보 보호 리스크 관리 | C19: 정보보호 / 정보보안 및 개인정보 보호 리스크 관리 | D19: 대웅제약은 법무자문을 통해 1개의 정책, 3개의 규정, 12개의 지침으로 구성된 정보보호 정책 체계를 재정비하여 운영하고 있습니다. 이러한 정책 체계는 임직원을 비롯하여 관계사 및 협력사 등 업무와 관련된 모든 이해관계자에게 공유하고 있으며, 이를 통해 전사적인 정책 준수를 권고하고 있습니다. 전사 정보보호 역량 강화를 위해 조직적, 인적, 물리적, 기술적 통제 영역 전반에 걸쳐 회사 기밀정보와 개인정보 보호 시스템을 종합적으로 분석하고 있으며, 이를 기반으로 수립한 체계적인 개선 로드맵을 충실히 이행하고 있습니다. 기술적 방어 체계의 구축뿐만 아니라 보안 캠페인, 공지, 정기 교육 등 임직원의 보안 인식을 제고하기 위한 다각적인 활동을 전개하고 있으며, 내부 정보 유출 및 이상 행위를 실시간으로 탐지하기 위한 모니터링 시스템을 상시 운영하여 리스크 대응력을 높이고 있습니다. 실질적인 보호대책 이행을 위해 세부 수행계획을 작성하고 배포하여 관련 담당자들의 실행력을 지원하고 있습니다. 그 결과, 관리 대상 항목 중 27개 항목에 대한 이행조치를 완료하였으며, 나머지 39개 항목에 대해서도 지속적으로 조치를 진행하며 보안 수준을 고도화하고 있습니다. 아울러 그룹 전체의 정보보호 수준을 상향 평준화하기 위해 대웅 관계사에 쉐어드 서비스를 제공하고 그룹사 보안 전략 수립을 지원함으로써, 관계사들이 대웅제약과 동일한 수준의 정보보안 관리체계를 안정적으로 운영할 수 있도록 통합적인 관리 체계를 구축하고 있습니다. | E19: 대웅제약은 ISO 27001(정보보안) 및 ISO 27701(개인정보보호) 인증을 유지하여 정보 자산과 고객 개인정보를 보호하고 있습니다. 법무자문을 통해 1개의 정책, 3개의 규정, 12개의 지침으로 구성된 정보보호 정책 체계를 재정비하였으며, 전문 모니터링 시스템을 구축하여 내부 정보 유출 및 이상 행위에 대해 상시 모니터링과 선제적 대응 체계를 운영하고 있습니다. 또한, 2024년에는 17개 점검 대상을 기준으로 정보보호 위험 식별 및 이행조치를 실시하여 미흡 항목에 대한 보호대책 이행을 지원하고 있으며, 해외 파트너사를 대상으로 보안 교육과 감사를 실시하여 정보 유출을 예방하고 있습니다. | F19: =IF(LEN(D19)>0,1,0) -> 1 | G19: =IF(LEN(E19)>0,1,0) -> 1 | H19: 739 | I19: 336 | J19: 7 | K19: 3 | L19: 104.7 | M19: 111.3 | N19: 0.307 | O19: 0.218 | P19: 0.9403 | Q19: 0.9283 | R19: 0.466 | S19: 0.693 | T19: 1 | U19: 0.6 | V19: 4.06 | W19: 2.98 | X19: 8 | Y19: 20 | Z19: 0 | AA19: 0 | AB19: =IF(AND($F19=1,$G19=1),IF(R19>S19,"V2",IF(S19>R19,"V3","동률")),"비교불가") -> V3 | AC19: =IF(AND($F19=1,$G19=1),IF(T19>U19,"V2",IF(U19>T19,"V3","동률")),"비교불가") -> V2 | AD19: Answer: passed / Consumer Decision: answered / QA Grade: full / Publication: published / Publication Reason: complete_grounded_answer / Coverage: complete_grounded_answer / RAG Coverage: complete / Answerable: True / Evidence: high_confidence
A20: EBX-Q-019 | B20: 사회 / 지표 (Metrics) / 개인정보 침해 및 정보보안 사고 현황 | C20: 정보보호 / 개인정보 침해 및 정보보안 사고 현황 | D20: 대웅제약은 정보보호 정책을 제정하고 매년 1회 이상 개정을 통해 전사적인 보안 역량을 강화하고 있습니다. 이러한 체계적인 관리 체계를 바탕으로 2022년 제약업계 최초로 정보보안관리 시스템인 ISO 27001과 개인정보보호 경영 시스템인 ISO 27701 국제 표준인증을 획득하였으며, 이를 3년 연속 유지하며 글로벌 수준의 보안 신뢰성을 확보하였습니다. 실질적인 정보보호 성과 측면에서는 대웅과 대웅제약 합산 기준으로 2022년부터 2025년까지 규제 기관에 의한 고객 사생활 또는 개인정보 침해 관련 불만 건수가 0건을 기록하며 안정적인 관리 상태를 유지하고 있습니다. 앞으로도 글로벌 수준의 강력한 보안 체계를 지속적으로 강화하고, 클라우드 보안 체계 구축 및 임직원 보안 인식 프로그램 확대 등을 통해 정보보호 관리체계를 더욱 발전시켜 나갈 계획입니다. | F20: =IF(LEN(D20)>0,1,0) -> 1 | G20: =IF(LEN(E20)>0,1,0) -> 0 | H20: 425 | I20: 0 | J20: 4 | K20: 0 | L20: 105.5 | M20: 0 | N20: 0.285 | O20: 0 | P20: 0.9547 | Q20: 0 | R20: 0.471 | S20: 0 | T20: 0.6 | U20: 0 | V20: 9.41 | W20: 0 | X20: 25 | Y20: 0 | Z20: 0 | AA20: 0 | AB20: =IF(AND($F20=1,$G20=1),IF(R20>S20,"V2",IF(S20>R20,"V3","동률")),"비교불가") -> 비교불가 | AC20: =IF(AND($F20=1,$G20=1),IF(T20>U20,"V2",IF(U20>T20,"V3","동률")),"비교불가") -> 비교불가 | AD20: Answer: failed / Consumer Decision: blocked_qa / QA Grade: failed / Publication: blocked / Publication Reason: qa_not_passed / Coverage: writer_empty / RAG Coverage: complete / Answerable: True / Evidence: high_confidence
A21: EBX-Q-020 | B21: 환경 / 전략 (Strategy) / 환경경영 정책 및 목표 | C21: 환경경영 / 환경경영 정책 및 목표 | D21: 대웅제약은 탄소배출 및 오염물질 저감 등 친환경 경영을 통한 무재해를 추구하며, 전 임직원의 철저한 책임의식과 적극적인 의무 이행 참여를 바탕으로 법적 규제 및 정해진 절차를 엄격히 준수하는 환경경영을 실현하고 있습니다. 이를 위해 ISO14001 환경경영시스템에 기반하여 관리 절차와 프로세스를 체계적으로 수립하고 운영함으로써, 제품 제조과정에서 발생할 수 있는 잠재적인 환경 문제와 기후변화 리스크에 선제적으로 대응하고 환경에 미치는 부정적인 영향을 최소화하는 데 주력하고 있습니다. 회사는 환경 관련 정보를 체계적으로 수집하고 평가하는 관리 체계를 구축하여 운영 중이며, 환경 개선을 위해 측정 가능한 목표를 설정하고 해당 목표의 적절성을 정기적으로 점검함으로써 실행력을 높이고 있습니다. 이러한 환경 성과 개선 노력은 단순한 기업 활동의 범위를 넘어 제품과 서비스의 개발 및 제공 전 과정으로 확대하여 지속적으로 추진하고 있습니다. 또한, 전 임직원을 대상으로 환경 관련 교육과 훈련을 정기적으로 실시함으로써 환경 경영에 대한 인식을 제고하고 실질적인 이행 역량을 강화하고 있습니다. 이를 통해 전사적인 환경 보호 및 지속가능한 운영 체계를 공고히 하며, 규제 준수를 넘어선 능동적인 환경 관리 문화를 정착시키고 있습니다. | E21: 대웅제약은 탄소배출 및 오염물질 저감 등 친환경 경영을 통한 무재해를 추구하며, ISO14001 환경경영시스템에 따라 관리 절차와 프로세스를 체계적으로 수립 및 운영하고 있습니다. 이를 통해 제품 제조과정에서 발생할 수 있는 환경 문제와 기후변화에 선제적으로 대응하여 환경에 미치는 부정적인 영향을 최소화하고 있습니다. 외부 평가 자료상 또한, 환경경영체제를 수립 및 유지하며 환경 개선을 위한 측정 가능한 목표를 설정하고 정기적으로 점검하며, 제품과 서비스의 개발 및 제공 과정에서 환경 성과를 개선하기 위한 노력을 지속하고 있습니다. | F21: =IF(LEN(D21)>0,1,0) -> 1 | G21: =IF(LEN(E21)>0,1,0) -> 1 | H21: 632 | I21: 300 | J21: 6 | K21: 3 | L21: 104.5 | M21: 99.3 | N21: 0.251 | O21: 0.181 | P21: 0.937 | Q21: 0.9242 | R21: 0.362 | S21: 0.718 | T21: 0.667 | U21: 0.667 | V21: 11.08 | W21: 6.67 | X21: 5 | Y21: 5 | Z21: 1 | AA21: 1 | AB21: =IF(AND($F21=1,$G21=1),IF(R21>S21,"V2",IF(S21>R21,"V3","동률")),"비교불가") -> V3 | AC21: =IF(AND($F21=1,$G21=1),IF(T21>U21,"V2",IF(U21>T21,"V3","동률")),"비교불가") -> 동률 | AD21: Answer: passed / Consumer Decision: answered_partial / QA Grade: cautious / Publication: review_required / Publication Reason: assessment_only / Coverage: assessment_only / RAG Coverage: complete / Answerable: True / Evidence: high_confidence
A22: EBX-Q-021 | B22: 환경 / 거버넌스 (Governance) / 환경경영 조직 및 책임 | C22: 환경경영 / 환경경영 조직 및 책임 | D22: 대웅그룹 EHS 경영위원회는 대표이사를 포함한 6인의 이사회 구성원으로 조직되어 환경안전 경영 체계를 감독하고 있습니다. 해당 위원회는 매년 대웅 그룹사의 환경안전 경영방침과 조직 현황, 활동 실적 및 KPI를 검토하며, 예산과 환경안전보건 사업계획을 승인함으로써 전사적인 환경경영의 책임과 실행력을 확보하고 있습니다. | E22: 대웅그룹은 대표이사를 포함한 6인으로 구성된 이사회를 통해 EHS 경영 조직을 운영하고 있습니다. 해당 조직은 매년 그룹사의 환경안전 경영방침, 조직현황, 활동실적, KPI, 예산 및 환경안전보건사업계획 등을 검토하고 승인하는 책임 체계를 갖추고 있습니다. | F22: =IF(LEN(D22)>0,1,0) -> 1 | G22: =IF(LEN(E22)>0,1,0) -> 1 | H22: 178 | I22: 143 | J22: 2 | K22: 2 | L22: 88.5 | M22: 71 | N22: 0.243 | O22: 0.239 | P22: 0.9474 | Q22: 0.9677 | R22: 0.368 | S22: 0.554 | T22: 1 | U22: 0.667 | V22: 0 | W22: 6.99 | X22: 1 | Y22: 1 | Z22: 0 | AA22: 0 | AB22: =IF(AND($F22=1,$G22=1),IF(R22>S22,"V2",IF(S22>R22,"V3","동률")),"비교불가") -> V3 | AC22: =IF(AND($F22=1,$G22=1),IF(T22>U22,"V2",IF(U22>T22,"V3","동률")),"비교불가") -> V2 | AD22: Answer: passed / Consumer Decision: answered_partial / QA Grade: partial / Publication: review_required / Publication Reason: missing_expected_facets / Coverage: missing_expected_facets / RAG Coverage: complete / Answerable: True / Evidence: high_confidence
A23: EBX-Q-022 | B23: 환경 / 위험 관리 (Risk Management) / 환경 영향 및 환경 리스크 관리 | C23: 환경경영 / 환경 영향 및 환경 리스크 관리 | D23: 비즈니스 운영과 제품 및 서비스 전반에서 발생할 수 있는 부정적인 환경 영향을 정기적으로 식별하고 평가하는 체계적인 관리 프로세스를 가동하고 있습니다. 특히 사업장 내 환경 리스크를 사전에 파악하고 이에 따른 개선 활동을 수행함으로써 잠재적 위험 요인을 선제적으로 관리하는 데 집중합니다. 이러한 리스크 관리 관점은 투자의사결정 단계까지 적용되어, 환경적 위험 및 기회 요인을 면밀히 검토하여 경영 전략에 반영하고 있습니다. 환경 및 환경권 보호를 위해 구체적이고 측정 가능하며 달성 가능한 정책과 목표를 수립하여 지속적으로 모니터링하고 있습니다. 이를 기반으로 환경 목표 및 성과 관리, 법규 준수, 에너지 및 온실가스 관리 등 주요 환경경영 활동을 체계적으로 이행하며 리스크 대응 역량을 강화하고 있습니다. 실질적인 환경 영향 저감을 위해 원자재와 에너지 사용을 최적화하고, 폐기물 및 온실가스 배출량을 감축하는 활동을 전개하여 환경 부하를 최소화하고 있습니다. 또한 모든 임직원을 대상으로 정기적인 환경 교육을 제공함으로써 전 구성원이 환경 리스크에 대한 인식을 제고하고 자발적으로 환경 경영을 실천하는 문화를 조성하고 있습니다. | E23: 외부 평가 자료상 대웅제약은 비즈니스 운영, 제품 또는 서비스와 관련된 부정적인 환경 영향을 정기적으로 식별하고 평가하고 있습니다. | F23: =IF(LEN(D23)>0,1,0) -> 1 | G23: =IF(LEN(E23)>0,1,0) -> 1 | H23: 579 | I23: 73 | J23: 7 | K23: 1 | L23: 81.9 | M23: 73 | N23: 0.104 | O23: 0 | P23: 0.8912 | Q23: 1 | R23: 0.34 | S23: 0.75 | T23: 1 | U23: 0.6 | V23: 6.91 | W23: 0 | X23: 0 | Y23: 0 | Z23: 1 | AA23: 0 | AB23: =IF(AND($F23=1,$G23=1),IF(R23>S23,"V2",IF(S23>R23,"V3","동률")),"비교불가") -> V3 | AC23: =IF(AND($F23=1,$G23=1),IF(T23>U23,"V2",IF(U23>T23,"V3","동률")),"비교불가") -> V2 | AD23: Answer: passed / Consumer Decision: answered_partial / QA Grade: cautious / Publication: review_required / Publication Reason: draft_evidence / Coverage: draft_evidence / RAG Coverage: complete / Answerable: True / Evidence: high_confidence
A24: EBX-Q-023 | B24: 환경 / 지표 (Metrics) / 환경 성과 지표 및 환경 사고 현황 | C24: 환경경영 / 환경 성과 지표 및 환경 사고 현황 | D24: 대웅제약은 에너지 효율 개선과 자원 순환 확대를 통해 환경 경영 성과를 관리하고 있습니다. 에너지 원단위의 경우 2025년 기준 65.86GJ/억원으로, 2024년의 68.23GJ/억원 대비 감소하며 전년도 목표였던 73.27GJ/억원을 달성하였습니다. 수자원 및 폐기물 관리 측면에서도 지속적인 개선을 추진하고 있습니다. 용수 재사용률은 2024년 7.23%에서 2025년 9.34%로 상승하였으며, 향후 2026년에는 14.7%까지 확대하는 것을 목표로 하고 있습니다. 폐기물 재활용률은 2024년 89.2%에 이어 2025년 89.1%를 기록하였으며, 2026년에는 90.2% 달성을 목표로 설정하여 자원 순환 체계를 강화하고 있습니다. | F24: =IF(LEN(D24)>0,1,0) -> 1 | G24: =IF(LEN(E24)>0,1,0) -> 0 | H24: 359 | I24: 0 | J24: 5 | K24: 0 | L24: 71 | M24: 0 | N24: 0.319 | O24: 0 | P24: 0.925 | Q24: 0 | R24: 0.348 | S24: 0 | T24: 0.5 | U24: 0 | V24: 5.57 | W24: 0 | X24: 62 | Y24: 0 | Z24: 0 | AA24: 0 | AB24: =IF(AND($F24=1,$G24=1),IF(R24>S24,"V2",IF(S24>R24,"V3","동률")),"비교불가") -> 비교불가 | AC24: =IF(AND($F24=1,$G24=1),IF(T24>U24,"V2",IF(U24>T24,"V3","동률")),"비교불가") -> 비교불가 | AD24: Answer: failed / Consumer Decision: blocked_qa / QA Grade: failed / Publication: blocked / Publication Reason: qa_not_passed / Coverage: writer_empty / RAG Coverage: complete / Answerable: True / Evidence: high_confidence
A25: EBX-Q-024 | B25: 거버넌스 / 전략 (Strategy) / 윤리경영 정책 및 목표 | C25: 윤리경영 / 윤리경영 정책 및 목표 | D25: 대웅제약은 임직원이 모든 업무 수행 과정에서 반드시 준수해야 할 윤리적 가치와 행동 원칙을 체계적으로 정의한 윤리규범을 수립하여 운영하고 있습니다. 이는 기업 경영의 투명성을 확보하고 사회적 책임을 다하기 위한 근간으로서, 전 임직원이 공유하는 윤리적 기준점이 됩니다. 더불어 윤리규범에 명시된 추상적인 원칙들을 실제 업무 현장에서 구체적으로 적용할 수 있도록 세부적인 지침과 기준을 담은 행동준칙을 마련하였습니다. 이러한 행동준칙은 임직원이 직면할 수 있는 다양한 상황에서 올바른 판단을 내릴 수 있도록 돕는 실무적인 가이드라인 역할을 수행하며, 윤리경영의 실행력을 실질적으로 높이는 데 기여하고 있습니다. 회사는 단순히 규범을 제정하는 것에 그치지 않고, 윤리규범과 행동준칙이 조직 내에서 실질적으로 이행될 수 있도록 다각적인 노력을 기울이고 있습니다. 이를 통해 윤리경영이 일시적인 캠페인이 아닌 기업 문화의 핵심 가치로 깊이 뿌리내릴 수 있도록 추진하고 있습니다. 나아가 대웅제약은 CP 운영과 윤리경영 체계를 더욱 공고히 구축하여 전사적인 CP 준수 문화를 정착시키는 데 주력하고 있습니다. 이러한 노력은 2026년에도 지속적으로 추진될 예정이며, 철저한 윤리·준법 경영을 통해 Global Healthcare Group이라는 기업 비전에 걸맞은 글로벌 수준의 경쟁력과 신뢰도를 갖춘 기업으로 성장해 나가고자 합니다. | E25: 대웅제약은 임직원이 업무 수행 과정에서 준수해야 할 윤리적 가치와 행동 원칙을 명시한 윤리규범과 이를 실제 업무에 적용하기 위한 구체적인 지침인 행동준칙을 운영하고 있습니다. 대외 관계에서의 정직과 성실 유지, 불공정한 청탁 및 부당 이익 취득 금지를 강조하며, 윤리규범 위반 행위에 대해서는 무관용 원칙을 적용하여 철저히 조사하고 조치하고 있습니다. 또한, CP(공정거래 자율준수 프로그램) 운영과 윤리경영을 공고히 하여 리베이트 없는 투명한 윤리 기업을 입증하고, 보다 강화된 윤리경영을 통해 신뢰받는 기업으로 거듭나는 것을 목표로 하고 있습니다. | F25: =IF(LEN(D25)>0,1,0) -> 1 | G25: =IF(LEN(E25)>0,1,0) -> 1 | H25: 686 | I25: 308 | J25: 8 | K25: 3 | L25: 84.9 | M25: 102 | N25: 0.236 | O25: 0.063 | P25: 0.9348 | Q25: 0.9743 | R25: 0.251 | S25: 0.532 | T25: 0.333 | U25: 0.667 | V25: 8.75 | W25: 3.25 | X25: 4 | Y25: 0 | Z25: 0 | AA25: 0 | AB25: =IF(AND($F25=1,$G25=1),IF(R25>S25,"V2",IF(S25>R25,"V3","동률")),"비교불가") -> V3 | AC25: =IF(AND($F25=1,$G25=1),IF(T25>U25,"V2",IF(U25>T25,"V3","동률")),"비교불가") -> V3 | AD25: Answer: passed / Consumer Decision: answered_partial / QA Grade: partial / Publication: review_required / Publication Reason: partial_answer / Coverage: partial_answer / RAG Coverage: insufficient / Answerable: False / Evidence: insufficient
A26: EBX-Q-025 | B26: 거버넌스 / 거버넌스 (Governance) / 윤리경영 조직 및 운영 체계 | C26: 윤리경영 / 윤리경영 조직 및 운영 체계 | D26: 대웅제약은 윤리경영 신문고를 운영하여 임직원의 고충 사항과 윤리규범 위반 제보, 제도 개선 의견 등을 상시 접수하고 있습니다. 이를 통해 조직 내 투명성과 청렴성을 강화하고 불공정 행위를 사전에 예방함으로써, 임직원이 함께 참여하는 건전한 기업문화를 조성하는 데 주력하고 있습니다. 신문고를 통한 제보 대상은 윤리규범 및 관련 법규를 위반하는 뇌물 수수, 부당거래, 성희롱 등의 행위를 포함하여 금품수수나 향응제공과 같이 건전한 기업문화를 저해하는 비윤리적 행위 전반으로 규정하고 있습니다. 아울러 단순한 위반 제보에 그치지 않고, 효율적인 업무 처리 방식이나 기업문화의 긍정적인 변화를 이끌어낼 수 있는 정책 개선 제안까지 폭넓게 접수하여 운영 체계의 실효성을 높이고 있습니다. 특히 제보자가 신분 노출이나 인사상 불이익에 대한 우려 없이 자유롭게 의견을 개진할 수 있도록 철저한 제보자 보호 원칙을 준수하고 있습니다. 제보자의 신원을 엄격히 보장하는 보호 체계를 통해 내부 신고 제도의 신뢰도를 확보하고, 이를 바탕으로 윤리경영 위반 사항을 체계적으로 관리하며 청렴한 조직 환경을 구축하고 있습니다. | E26: 대웅제약은 공정거래 관련 법규의 자율적 준수를 위해 CP(공정거래자율준수프로그램)를 운영하고 있습니다. 9명으로 구성된 CP 전담조직을 중심으로 교육, 모니터링, 제재, 평가 체계를 구축하여 운영 중이며, CP위원회 운영과 제품설명회 상시 점검, 위반자 징계조치 등을 수행하고 있습니다. 또한 그룹 관계사 지원 및 파트너사 정기감사 대응을 통해 투명한 준법경영 체계를 강화하고 있습니다. | F26: =IF(LEN(D26)>0,1,0) -> 1 | G26: =IF(LEN(E26)>0,1,0) -> 1 | H26: 561 | I26: 216 | J26: 6 | K26: 3 | L26: 92.7 | M26: 71.3 | N26: 0.173 | O26: 0.304 | P26: 0.9568 | Q26: 0.945 | R26: 0.302 | S26: 0.693 | T26: 1 | U26: 0.75 | V26: 5.35 | W26: 9.26 | X26: 0 | Y26: 1 | Z26: 0 | AA26: 0 | AB26: =IF(AND($F26=1,$G26=1),IF(R26>S26,"V2",IF(S26>R26,"V3","동률")),"비교불가") -> V3 | AC26: =IF(AND($F26=1,$G26=1),IF(T26>U26,"V2",IF(U26>T26,"V3","동률")),"비교불가") -> V2 | AD26: Answer: passed / Consumer Decision: answered_partial / QA Grade: partial / Publication: review_required / Publication Reason: missing_expected_facets / Coverage: missing_expected_facets / RAG Coverage: insufficient / Answerable: False / Evidence: insufficient
A27: EBX-Q-026 | B27: 거버넌스 / 위험 관리 (Risk Management) / 윤리 및 준법 리스크 관리 | C27: 윤리경영 / 윤리 및 준법 리스크 관리 | D27: 대웅제약은 국내외 법규 및 규정을 철저히 준수하고 기업 윤리를 강화함으로써 법규 리스크를 최소화하는 데 주력하고 있습니다. 특히 ISO37001 부패방지경영시스템을 기반으로 부패리스크 평가, 내부심사, 사후심사 및 경영검토를 수행하며 준법·윤리경영 체계를 고도화하고 인증을 유지하고 있습니다. 공정하고 투명한 영업 및 마케팅 문화 정착을 위해 경제적 이익 지출보고 및 모니터링 체계를 강화하고 있습니다. 제품설명회, 견본품 제공, 학회참가 및 임상시험 지원, 시판 후 조사 등 항목별 지출내역을 작성 및 보관하여 심평원에 제출하고 있으며, 지출관리 시스템 개선과 영업부 운영기준 강화를 통해 관리 체계를 정교화하였습니다. 또한 영업·마케팅 비용 사용 내역에 대한 상시 점검과 법인카드 사용 모니터링 시나리오를 세분화하여 리스크를 선제적으로 관리합니다. 준법경영의 실천력을 높이기 위해 CP(공정거래자율준수프로그램) 전담조직을 설치하여 불공정 거래 리스크를 제거하고 있으며, 임직원을 대상으로 공정거래 및 부패방지 서약과 교육을 운영하고 있습니다. 아울러 CSO 신고제 대응을 위해 의약품 및 의료기기 판촉영업자 신고를 완료하고 관련 의무교육 수료를 진행하는 등 법적 준거성을 확보하고 있습니다. 이와 함께 주요 부서들은 법규 변화에 따라 내부통제 정책을 지속적으로 개선 및 보완하며 사업 운영 전반의 리스크를 효율적으로 관리하고 있습니다. | E27: 대웅제약은 부패 및 법규 리스크를 최소화하기 위해 ISO 37001(부패방지경영시스템) 인증을 취득하여 국제 표준 기반의 경영 시스템을 구축 및 운영하고 있으며, 부패리스크 평가, 내부심사, 사후심사 및 경영검토를 통해 체계를 고도화하고 있습니다. 또한 공정거래법, 약사법 등 관련 법규의 자율적 준수를 위해 공정거래자율준수프로그램(CP)을 운영하고 있으며, 이를 전담하는 CP 전담조직을 설치하여 불공정 거래 리스크를 관리하고 있습니다. 이와 함께 경제적 이익 지출보고 및 모니터링 체계 강화, 전사 부패방지 교육 및 임직원 서약 실시, CSO 신고제 대응 등을 통해 투명한 영업 마케팅 문화를 정착시키고 관련 법규 변화에 따라 내부통제 정책을 지속적으로 개선하고 있습니다. | F27: =IF(LEN(D27)>0,1,0) -> 1 | G27: =IF(LEN(E27)>0,1,0) -> 1 | H27: 693 | I27: 378 | J27: 8 | K27: 3 | L27: 85.8 | M27: 125.3 | N27: 0.225 | O27: 0.111 | P27: 0.93 | Q27: 0.9314 | R27: 0.513 | S27: 0.581 | T27: 1 | U27: 0.5 | V27: 5.77 | W27: 10.58 | X27: 5 | Y27: 5 | Z27: 0 | AA27: 0 | AB27: =IF(AND($F27=1,$G27=1),IF(R27>S27,"V2",IF(S27>R27,"V3","동률")),"비교불가") -> V3 | AC27: =IF(AND($F27=1,$G27=1),IF(T27>U27,"V2",IF(U27>T27,"V3","동률")),"비교불가") -> V2 | AD27: Answer: passed / Consumer Decision: answered / QA Grade: full / Publication: published / Publication Reason: complete_grounded_answer / Coverage: complete_grounded_answer / RAG Coverage: complete / Answerable: True / Evidence: high_confidence
A28: EBX-Q-027 | B28: 거버넌스 / 지표 (Metrics) / 윤리 위반 및 준법 관련 사건 현황 | C28: 윤리경영 / 윤리 위반 및 준법 관련 사건 현황 | D28: 대웅과 대웅제약 합산 기준으로 윤리 및 준법 경영 성과를 통합 관리하고 있습니다. 징계 합계 건수는 2022년 1건에서 2023년 8건, 2024년 11건을 거쳐 2025년에는 19건으로 집계되었습니다. 징계 세부 항목 중 관리감독 소홀은 2023년 5건, 2024년 2건, 2025년 2건이 발생한 것으로 확인됩니다. 법규 및 규제 위반과 관련하여 벌금 또는 처벌을 받은 사건은 2022년과 2023년에 각각 2건씩 발생하였으나, 2024년과 2025년에는 발생하지 않았습니다. 사례별 위반 현황을 살펴보면, 국내 마케팅 활동에 관한 광고 위반은 2022년 2건, 2023년 1건, 2025년 1건이 확인되었으며, 여기에는 2023년 우루샷 광고 업무 행정처분과 2025년 임팩타민프리미엄원스정 광고업무정지 사례가 포함됩니다. 기타 규정 위반의 경우 2022년 1건, 2023년 1건, 2024년 3건, 2025년 1건이 발생하였습니다. 주요 사례로는 2023년 페노스탑 제조업무정지 3개월과 2024년 주플리외용액 자진회수, 엘도스시럽 회수폐기명령, 클로아트 영업자회수조치 등이 있습니다. 아울러 직장 내 괴롭힘 및 법인카드 부정사용 등 CP 기준 위반자에 대해서는 인사위원회 회부를 통해 감봉 3개월 이상의 중징계를 시행하는 등 엄격한 윤리 기준을 적용하여 관리하고 있습니다. | F28: =IF(LEN(D28)>0,1,0) -> 1 | G28: =IF(LEN(E28)>0,1,0) -> 0 | H28: 661 | I28: 0 | J28: 8 | K28: 0 | L28: 81.8 | M28: 0 | N28: 0.337 | O28: 0 | P28: 0.9104 | Q28: 0 | R28: 0.309 | S28: 0 | T28: 1 | U28: 0 | V28: 0 | W28: 0 | X28: 107 | Y28: 0 | Z28: 0 | AA28: 0 | AB28: =IF(AND($F28=1,$G28=1),IF(R28>S28,"V2",IF(S28>R28,"V3","동률")),"비교불가") -> 비교불가 | AC28: =IF(AND($F28=1,$G28=1),IF(T28>U28,"V2",IF(U28>T28,"V3","동률")),"비교불가") -> 비교불가 | AD28: Answer: failed / Consumer Decision: blocked_qa / QA Grade: failed / Publication: blocked / Publication Reason: qa_not_passed / Coverage: writer_empty / RAG Coverage: complete / Answerable: True / Evidence: high_confidence
A29: EBX-Q-028 | B29: 환경 / 전략 (Strategy) / 온실가스 감축 전략 및 탄소중립 목표 | C29: 기후행동 / 온실가스 감축 전략 및 탄소중립 목표 | D29: 최고경영진의 책임 아래 도전적인 목표와 실행계획을 수립하고, 정기적인 점검과 평가를 통해 경영시스템의 실효성을 지속적으로 고도화하고 있습니다. 대웅제약은 탄소중립 실현과 환경영향 최소화를 핵심 전략 방향으로 설정하여 친환경 원자재의 사용을 확대하고, 온실가스 저감과 오염 예방 및 자원순환 활동을 활성화하는 데 주력하고 있습니다. 특히 대기, 수질, 폐기물, 화학물질 등 주요 환경영향 요인을 선제적으로 관리하는 체계를 운영하고 있으며, 친환경 기술혁신과 공정 개선을 통해 제품의 전 과정에서 발생하는 환경영향을 최소화함으로써 탄소중립 실현과 생태계 보전에 앞장서고 있습니다. 에너지 경영 측면에서는 고효율 설비와 제품, 서비스의 도입을 우선적으로 검토하는 원칙을 적용하고 있습니다. 공정이나 설비를 신설하거나 변경하는 과정에서 에너지 효율 향상 요소를 적극적으로 반영함으로써 책임 있는 에너지 경영을 실천하고 있습니다. 이와 더불어 에너지 사용과 소비를 체계적으로 관리하여 에너지 효율 향상과 사용 최적화를 지속적으로 추진하고 있습니다. 구체적인 이행 관리를 위해 에너지 절감량, 비용 절감액, 온실가스 감축 효과를 관리함으로써 전사적인 자원 효율성을 제고하고 기후변화 대응 역량을 강화하고 있습니다. 이러한 체계적인 에너지 관리와 사용 최적화 활동을 통해 온실가스 배출을 줄이고 지속 가능한 경영 기반을 공고히 하고 있습니다. | E29: 대웅제약은 친환경 원자재 사용 확대, 온실가스 저감, 오염 예방 및 자원순환 활동 활성화를 통해 탄소중립 실현과 환경영향 최소화를 추진하고 있습니다. 이를 위해 친환경 기술혁신과 공정 개선을 통해 제품 전 과정의 환경영향을 최소화하며, 에너지 사용 및 소비의 체계적 관리와 고효율 설비 도입, 공정 운영 최적화를 통한 에너지 효율 향상을 지속적으로 추진하고 있습니다. | F29: =IF(LEN(D29)>0,1,0) -> 1 | G29: =IF(LEN(E29)>0,1,0) -> 1 | H29: 688 | I29: 205 | J29: 8 | K29: 2 | L29: 85.1 | M29: 102 | N29: 0.279 | O29: 0.186 | P29: 0.9216 | Q29: 0.9021 | R29: 0.553 | S29: 0.543 | T29: 1 | U29: 0.4 | V29: 13.08 | W29: 14.63 | X29: 0 | Y29: 0 | Z29: 0 | AA29: 0 | AB29: =IF(AND($F29=1,$G29=1),IF(R29>S29,"V2",IF(S29>R29,"V3","동률")),"비교불가") -> V2 | AC29: =IF(AND($F29=1,$G29=1),IF(T29>U29,"V2",IF(U29>T29,"V3","동률")),"비교불가") -> V2 | AD29: Answer: passed / Consumer Decision: answered_partial / QA Grade: partial / Publication: review_required / Publication Reason: missing_expected_facets / Coverage: missing_expected_facets / RAG Coverage: insufficient / Answerable: False / Evidence: insufficient
A30: EBX-Q-029 | B30: 환경 / 거버넌스 (Governance) / 기후변화 대응 조직 및 관리 체계 | C30: 기후행동 / 기후변화 대응 조직 및 관리 체계 | D30: 대웅제약은 기후변화 대응과 환경영향 최소화를 위해 이사회, ESG위원회, 대웅그룹 EHS 경영위원회, EHS 간사협의체로 구성된 환경경영 거버넌스를 운영하고 있습니다. ESG위원회는 전사 ESG 전략과 기후변화 및 탄소배출 등 주요 지속가능경영 이슈를 검토하고 심의하는 역할을 수행합니다. 이와 함께 대웅그룹 EHS 경영위원회는 환경·안전·보건(EHS) 분야의 정책과 목표 및 실행과제를 수립하며, 이에 대한 이행 현황을 점검함으로써 기후변화 대응 체계를 관리하고 있습니다. | E30: 검토 중인 제안 자료상 ESG위원회는 전사 ESG 전략과 기후변화 및 탄소배출 등 주요 지속가능경영 이슈를 검토하고 심의하는 역할을 수행합니다. 또한, 대웅그룹 EHS 경영위원회는 환경 안전 보건(EHS) 분야의 정책, 목표 및 실행과제를 수립하고 이행 현황을 점검하고 있습니다. | F30: =IF(LEN(D30)>0,1,0) -> 1 | G30: =IF(LEN(E30)>0,1,0) -> 1 | H30: 265 | I30: 156 | J30: 3 | K30: 2 | L30: 87.7 | M30: 77.5 | N30: 0.173 | O30: 0.032 | P30: 0.9105 | Q30: 0.9459 | R30: 0.718 | S30: 0.685 | T30: 0.8 | U30: 0.2 | V30: 3.77 | W30: 0 | X30: 0 | Y30: 0 | Z30: 1 | AA30: 0 | AB30: =IF(AND($F30=1,$G30=1),IF(R30>S30,"V2",IF(S30>R30,"V3","동률")),"비교불가") -> V2 | AC30: =IF(AND($F30=1,$G30=1),IF(T30>U30,"V2",IF(U30>T30,"V3","동률")),"비교불가") -> V2 | AD30: Answer: passed / Consumer Decision: answered_partial / QA Grade: cautious / Publication: review_required / Publication Reason: draft_evidence / Coverage: draft_evidence / RAG Coverage: insufficient / Answerable: False / Evidence: insufficient
A31: EBX-Q-030 | B31: 환경 / 위험 관리 (Risk Management) / 기후 리스크 및 기회 관리 | C31: 기후행동 / 기후 리스크 및 기회 관리 | D31: 기후 리스크 및 기회 요인을 물리적 리스크(급성, 만성), 전환 리스크(정책 및 법률, 기술, 시장, 평판), 기회(자원 효율성, 에너지원, 제품 서비스, 시장, 회복탄력성)로 유형화하였으며, 각 요인이 사업 운영과 가치사슬에 미치는 영향을 검토하여 대응 방향과 관리 지표를 연계해 운영하고 있습니다. 특히 기후대응 공시 및 성과 요구 확대에 따른 온실가스 배출량 관리, 감축 성과 달성, 에너지 효율 개선 및 신재생 설비 도입을 위한 투자 부담 증가를 주요 전환 리스크로 식별하였습니다. 리스크 대응 실행력을 강화하기 위해 환경규제, 탄소가격, 공시 요구와 더불어 극한기상 및 평균기온 상승 등 주요 요인에 대한 배출량, 에너지 사용량, 검증 수준, 피해 현황을 지속적으로 모니터링하고 있습니다. 동시에 기후변화 대응을 통한 사업적 기회 창출에도 집중하고 있습니다. 친환경 포장, 저탄소 제조 및 환경영향 저감형 제품에 대한 고객과 공공조달 수요 확대에 대응하여 저탄소 의약품 시장을 확대하고 있으며, 이중소싱과 백업 제조시설 확보, 원료 조달처 다변화를 통해 기후 및 지정학적 요인으로 인한 공급 차질 리스크를 완화하고 사업의 회복탄력성을 강화하고 있습니다. | E31: 환경규제, 탄소가격, 공시 요구, 극한기상, 평균기온 상승 등 주요 요인에 대해 배출량, 에너지 사용량, 검증 수준, 피해 현황 등을 모니터링하며 기후 리스크 대응 실행력을 강화하고 있습니다. | F31: =IF(LEN(D31)>0,1,0) -> 1 | G31: =IF(LEN(E31)>0,1,0) -> 1 | H31: 594 | I31: 107 | J31: 5 | K31: 1 | L31: 118 | M31: 107 | N31: 0.401 | O31: 0 | P31: 0.9385 | Q31: 1 | R31: 0.576 | S31: 0 | T31: 1 | U31: 0.5 | V31: 5.05 | W31: 9.35 | X31: 0 | Y31: 0 | Z31: 0 | AA31: 0 | AB31: =IF(AND($F31=1,$G31=1),IF(R31>S31,"V2",IF(S31>R31,"V3","동률")),"비교불가") -> V2 | AC31: =IF(AND($F31=1,$G31=1),IF(T31>U31,"V2",IF(U31>T31,"V3","동률")),"비교불가") -> V2 | AD31: Answer: passed / Consumer Decision: answered_partial / QA Grade: partial / Publication: review_required / Publication Reason: missing_expected_facets / Coverage: missing_expected_facets / RAG Coverage: partial / Answerable: True / Evidence: thin_but_usable
A32: EBX-Q-031 | B32: 환경 / 지표 (Metrics) / 온실가스 배출량 및 에너지 사용 현황 | C32: 기후행동 / 온실가스 배출량 및 에너지 사용 현황 | D32: 대웅제약은 사업장 내 에너지 사용 효율을 높이고 온실가스 배출량을 체계적으로 관리하여 기후변화 대응 역량을 강화하고 있습니다. 2025년 기준 총 온실가스 배출량(Scope 1+2)은 44,144.431tCO2e를 기록하였으며, 이 중 직접배출(Scope 1)인 LNG 등은 12,771.822tCO2e, 간접배출(Scope 2)인 전력 사용으로 인한 배출량은 31,372.609tCO2e로 집계되었습니다. 에너지 사용 현황을 살펴보면, 2025년 총 에너지 사용량은 916,158.011GJ로 전년 대비 증가하는 추세를 보이고 있습니다. 세부적으로는 간접에너지인 전력이 664,073.68GJ로 가장 큰 비중을 차지하며, 직접에너지인 LNG 사용량은 251,731.763GJ, 경유는 352.568GJ를 사용하였습니다. 매출액 대비 에너지 사용 원단위는 65.863GJ/억원으로 관리되고 있습니다. 에너지 효율 개선을 위한 저감 활동을 통해 실질적인 탄소 배출 감소를 추진하고 있습니다. 2025년 기준 에너지 절감량은 38,352.29GJ를 달성하였으며, 이를 통한 탄소배출 저감량은 1,908.486tCO2e로 확인됩니다. 특히 향남공장에서는 대기방지시설 개선과 고온연수기 정비 등의 설비 최적화를 통해 에너지 소비를 줄이고 배출량을 낮추는 성과를 거두었습니다. | F32: =IF(LEN(D32)>0,1,0) -> 1 | G32: =IF(LEN(E32)>0,1,0) -> 0 | H32: 653 | I32: 0 | J32: 8 | K32: 0 | L32: 80.8 | M32: 0 | N32: 0.409 | O32: 0 | P32: 0.9224 | Q32: 0 | R32: 0.209 | S32: 0 | T32: 1 | U32: 0 | V32: 4.59 | W32: 0 | X32: 95 | Y32: 0 | Z32: 0 | AA32: 0 | AB32: =IF(AND($F32=1,$G32=1),IF(R32>S32,"V2",IF(S32>R32,"V3","동률")),"비교불가") -> 비교불가 | AC32: =IF(AND($F32=1,$G32=1),IF(T32>U32,"V2",IF(U32>T32,"V3","동률")),"비교불가") -> 비교불가 | AD32: Answer: failed / Consumer Decision: blocked_qa / QA Grade: failed / Publication: blocked / Publication Reason: qa_not_passed / Coverage: writer_empty / RAG Coverage: complete / Answerable: True / Evidence: high_confidence
